Workbook

Sheet Справка
A1: РАСЧЕТ
A2: стоимости вновь начинаемого объекта дорожных работ (от 10.04.2026)
A4: Государственный заказчик | B4: Краевое государственное казенное учреждение "Управление автомобильных дорог Камчатского края"
A5: Наименование объекта | B5: Строительство причальных сооружений через протоку Озерная в Усть-Камчатском районе Камчатского края
B6: Стоимость работ в ценах на дату утверждения сметной документации 1 квартал 2022 года | C6: Выполнение | D6: Экономия | E6: Стоимость остатка работ в ценах утверждения ПСД, 1 квартал 2022 года | F6: Индекс фактической инфляции | H6: Стоимость работ в ценах на дату формирования начальной (максимальной) цены контракта | K6: Индекс прогнозной инфляции на период выполнения работ Кинф= Д1*К1+Д2*К2+Д3*К3 | M6: Начальная (максимальная) цена контракта с учетом индекса прогнозной инфляции на период выполнения работ | Q6: в том числе по годам | Z6: Стоимость в ценах соответствующих лет | AA6: Подлежит выполнению до конца строительства в ценах соответствующих лет
W7: 2026 (апрель - декабрь) | Y7: 2027 (январь-октябрь) | AB7: 2022 | AC7: 2023 | AD7: 2024
A8: 1 | B8: 2 | C8: 3 | D8: 4 | E8: 5 | F8: 6 | H8: 7 | K8: 8 | M8: 9 | Q8: 10 | W8: 12 | Y8: 13 | Z8: 14 | AA8: 15
A9: Стоимость всего | B9: =B11+B14 -> 271528193 | C9: =C11+C14 -> 12699227 | E9: =E11+E14 -> 258828966 | H9: =H11+H14 -> 3.5476653e+08 | M9: =M11+M14 -> 3.9555597e+08 | W9: =W11+W14 -> 1.1677987e+08 | Y9: =Y11+Y14+0.001 -> 2.787761e+08 | Z9: =Z11+Z14+0.001 -> 4.082552e+08 | AA9: =AA11+AA14+0.001 -> 3.9555597e+08 | AB9: =(U9+C9)/Z9 -> 0.031 | AC9: =(C9+U9+W9)/Z9 -> 0.317 | AD9: =(C9+Y9+U9+W9)/Z9 -> 1
A10: в том числе
A11: Затраты заказчика | B11: =B12+B13 -> 17942395 | C11: =C12+C13 -> 12699227 | E11: =B11-C11 -> 5243168 | F11: =F15 -> 1.399 | M11: =SUM(M12:P13) -> 14050688 | W11: =W12+W13 -> 2328289 | Y11: =Y12 -> 11722399 | Z11: =Z12+Z13 -> 26749915 | AA11: =AA12+AA13 -> 14050688
A12: индексируемые | B12: =Затраты!J11*1000 -> 6243145 | C12: =Затраты!B11*1000 -> 999977 | E12: =B12-C12 -> 5243168 | M12: =U12+W12+Y12 -> 14050688 | W12: =Затраты!E10*Справка!F15*Справка!K15*1000 -> 2328289 | Y12: =Затраты!F10*Справка!F15*Справка!K15*1000 -> 11722399 | Z12: =M12+C12 -> 15050665 | AA12: =M12 -> 14050688
A13: неиндексируемые | B13: =Затраты!I22*1000 -> 11699250 | C13: =Затраты!B22*1000 -> 11699250 | E13: =B13-C13 -> 0 | Z13: =M13+C13 -> 11699250 | AA13: =E13 -> 0 | AB13: =Z9-C9 -> 3.9555597e+08
A14: Затраты подрядчика | B14: =B15+B16 -> 253585798 | E14: =E15+E16 -> 253585798 | H14: =SUM(H15:J16) -> 3.5476653e+08 | M14: =SUM(M15:P16) -> 3.8150528e+08 | W14: =W15+W16 -> 1.1445159e+08 | Y14: =Y15 -> 2.670537e+08 | Z14: =Z15+Z16 -> 3.8150528e+08 | AA14: =AA15+AA16 -> 3.8150528e+08
A15: индексируемые | B15: =Затраты!J26*1000 -> 253585798 | E15: =B15-C15-D15 -> 253585798 | F15: =C41 -> 1.399 | H15: =E15*F15 -> 3.5476653e+08 | K15: =W56 -> 1.07537 | M15: =H15*K15 -> 3.8150528e+08 | W15: =Затраты!E26*1000*Справка!K15*Справка!F15 -> 1.1445159e+08 | Y15: =Затраты!F26*Справка!F15*Справка!K15*1000 -> 2.670537e+08 | Z15: =M15+C15 -> 3.8150528e+08 | AA15: =M15 -> 3.8150528e+08
A16: неиндексируемые | B16: 0
A17: В зависимости от года утверждения ПСД и планируемого выполнения работ по годам исполнения государственного контракта таблица может быть откорректирована.
A19: Дата формирования НМЦК - | B19: апрель 2026 года | X19: из расчета 30% аванса в 2026г. = | AA19: =AA14*0.3 -> 1.1445159e+08
A20: Начало строительства - июнь 2026 года
A21: Окончание строительства - октябрь 2027 года
A23: 1. Расчет индексов фактической инфляции с использованием ИПЦ Росстата (Камчатский край):
A24: март 2023 / март 2022 | B24: 108.6 | C24: =B24/100 -> 1.086
A25: март 2024 / март 2023 | B25: 109.53 | C25: =B25/100 -> 1.0953 | AC25: 2025 = | AD25: 1.082
A26: март 2025 / март 2024 | B26: 106.56 | C26: =B26/100 -> 1.0656
A27: 45748 | B27: 98.08 | C27: =B27/100 -> 0.9808
A28: 45778 | B28: 101.17 | C28: =B28/100 -> 1.0117 | AC28: 2026 = | AD28: 1.078
A29: 45809 | B29: 103.19 | C29: =B29/100 -> 1.0319
A30: 45839 | B30: 100.64 | C30: =B30/100 -> 1.0064
A31: 45870 | B31: 100.15 | C31: =B31/100 -> 1.0015
A32: 45901 | B32: 102.06 | C32: =B32/100 -> 1.0206
A33: 45931 | B33: 100.26 | C33: =B33/100 -> 1.0026
A34: 45962 | B34: 100.86 | C34: =B34/100 -> 1.0086 | E34: 2. Расчет индекса прогнозной инфляции (Уточненный прогноз социально-экономического развития Камчатского края на 2026 год и на плановый период 2027 и 2028 годов от 19 ноября 2025, отрасль "Инвестиции в основной капитал"):
A35: 45992 | B35: 100.46 | C35: =B35/100 -> 1.0046
A36: 46023 | B36: 101.14 | C36: =B36/100 -> 1.0114
A37: 46054 | B37: 100.99 | C37: =B37/100 -> 1.0099
A38: 46082 | B38: 100.99 | C38: =B38/100 -> 1.0099
E40: 2026 = | K40: 12 | L40: √ | M40: =F41 -> 1.078 | N40: = | O40: =M40^(1/K40) -> 1.0063
B41: Индекс фактической инфляции | C41: =C25*C26*C24*C27*C28*C29*C30*C31*C32*C33*C34*C35*C36*C37*C38 -> 1.399 | F41: 1.078
E43: 2027 = | K43: 12 | L43: √ | M43: =F44 -> 1.077 | N43: = | O43: =M43^(1/K43) -> 1.0062
F44: 1.077
A46: Доля сметной стоимости, подлежащая выполнению подрядчиком в 2026 году (Дп2) - | E46: =Затраты!E26/Затраты!J26 -> 0.3 | G46: Доля сметной стоимости, подлежащая выполнению заказчиком в 2026 году (Дз2) - | V46: =Затраты!E10/(Затраты!J10-Затраты!B10) -> 0.29517
...

Sheet Затраты
E1: Приложение № 3 к Порядку взаимодействия при рассмотрении стоимостных показателей объектов строительства, реконструкции, капитального ремонта автомобильных дорог и искусственных дорожных сооружений, частично или полностью финансируемых за счет средств федерального бюджета, утвержденному Приказом от 28.07.2021 № 154
A3: Справка о затратах заказчика и затратах подрядчика в составе сводного сметного расчета с расшифровкой по видам затрат
A5: Заказчик: Краевое государственное казенное учреждение "Управление автомобильных дорог Камчатского края"
A6: Наименование объекта: Строитсльство причальных сооружений через протоку Озерная в Усть-Камчатском районе Камчатского края
A8: Наименование работ и затрат | B8: Распределение затрат по годам, тыс. руб. в ценах 1 кв. 2022 г (в уровне цен утвержденной проектной документации) | K8: Обоснование
B9: До 2022 (выполнено) | D9: 2025 | E9: 2026 | F9: 2027 | G9: Экономия | I9: ВСЕГО с НДС 20% | J9: НДС 22% | O9: =F10+E10 -> 9339.464
A10: 1. Затраты заказчика | B10: =B11+B22 -> 12699.227 | D10: =D11+D22 -> 0 | E10: =E11+E22 -> 1547.609 | F10: =F11+F22 -> 7791.855 | G10: =G11+G22 -> 0 | H10: =H11+H22 -> 16486.85 | I10: =I11+I22 -> 17840.047 | J10: =J11+J22 -> 17942.395 | M10: =SUM(B10:G10)-I10 -> 4198.644 | O10: =E10/O9 -> 0.1657064
A11: - индексируемые | B11: =SUM(B12:B18) -> 999.977 | D11: =SUM(D12:D18) -> 0 | E11: =SUM(E12:E18) -> 1547.609 | F11: =SUM(F12:F18) -> 7791.855 | G11: =SUM(G12:G18) -> 0 | H11: =SUM(H12:H18) -> 4787.6 | I11: =SUM(I12:I18) -> 6140.797 | J11: =SUM(J12:J18) -> 6243.145 | M11: =SUM(B11:G11)-I11 -> 4198.644 | O11: =F10/O9 -> 0.8342936
A12: Восстановление оси трассы | E12: =I12-C12-D12 -> 0 | M12: =SUM(B12:G12)-I12 -> 0
A13: Ущерб водным биоресурсам | F13: =J13 -> 632.973 | H13: =173.51+345.32 -> 518.83 | I13: =(173.51+345.32)*1.2 -> 622.596 | J13: =(173.51+345.32)*1.22 -> 632.973 | M13: =SUM(B13:G13)-I13 -> 10.377
E14: =I14-C14-D14 -> 0 | M14: =SUM(B14:G14)-I14 -> 0
A15: Технологическое присоединение к электрическим сетям | F15: =J15 -> 49.203 | H15: =39.86+0.47 -> 40.33 | I15: =(39.86+0.47)*1.2 -> 48.396 | J15: =(39.86+0.47)*1.22 -> 49.203 | M15: =SUM(B15:G15)-I15 -> 0.807
A16: Строительный контроль | E16: =J16/J27*E26 -> 1547.609 | F16: =J16-E16 -> 3611.088 | H16: 4228.44 | I16: =4228.44*1.2 -> 5074.128 | J16: =4228.44*1.22 -> 5158.697 | L16: =I16/(I28+I36+I45) -> 0.021398927 | M16: =SUM(B16:G16)-I16 -> 84.569 | O16: =J13+J15+J16+J30+J31+J32+J36+J43 -> 254454.4 | P16: =O16/1.22 -> 208569.18
A17: Авторский надзор | E17: =J17/2 -> 0 | F17: ='НМЦК АН'!B18/1000 -> 498.591 | L17: =(I28+I36+I45)*0.2% -> 474.24134 | M17: =SUM(B17:G17)-I17 -> 498.591 | O17: =J17+J18+J47 -> 5374.543 | P17: =O17/1.22 -> 4405.3631 | Q17: =P17*1.22 -> 5374.543 | R17: =4405.36*1.22 -> 5374.5392
A18: Непредвиденные затраты: | B18: =SUM(B19:B21) -> 999.977 | D18: =SUM(D19:D21) -> 0 | E18: =SUM(E19:E21) -> 0 | F18: =SUM(F19:F21) -> 3000 | G18: =SUM(G19:G21) -> 0 | I18: =SUM(I19:I21) -> 395.677 | J18: =SUM(J19:J21) -> 402.272 | M18: =SUM(B18:G18)-I18 -> 3604.3 | O18: =J22 -> 11699.25 | R18: =R17/1.22 -> 4405.36
A19: Непредвиденные затраты от прочих затрат заказчика | H19: =(H13+H15+H16+H22)*2% -> 329.737 | I19: =(I13+I15+I16+I22)*2%+I22*0.2*2%-0.007 -> 395.677 | J19: =(J13+J15+J16+J22)*2%+J22*0.22*2%-0.007 -> 402.272 | M19: =SUM(B19:G19)-#REF! -> #REF!
A20: Резерв на непредвиденные работы и затраты от прочих затрат подрядчика (1%) | F20: =J20 -> 0 | L20: =L21+F20+F19+F15+F13 -> #REF! | M20: =SUM(B20:G20)-I19 -> -395.677
A21: Резерв на непредвиденные работы и затраты от СМР (1%) | B21: =O26-B22 -> 999.977 | F21: 3000 | L21: =F21-#REF!/1000 -> #REF! | M21: =SUM(B21:G21)-I21 -> 3999.977
A22: - неиндексируемые | B22: =SUM(B23:B25) -> 11699.25 | D22: =SUM(D23:D25) -> 0 | E22: =SUM(E23:E25) -> 0 | F22: =SUM(F23:F25) -> 0 | G22: =SUM(G23:G25) -> 0 | H22: =SUM(H23:H25) -> 11699.25 | I22: =SUM(I23:I25) -> 11699.25 | J22: =J24+J25 -> 11699.25 | M22: =SUM(B22:G22)-I22 -> 0
A23: Инженерные изыскания | M23: =SUM(B23:G23)-I23 -> 0
A24: Проектные работы | B24: =I24 -> 10000 | H24: 10000 | I24: 10000 | J24: =I24 -> 10000 | M24: =SUM(B24:G24)-I24 -> 0
A25: Экспертиза проекта | B25: =I25 -> 1699.25 | H25: 1699.25 | I25: 1699.25 | J25: =I25 -> 1699.25 | M25: =SUM(B25:G25)-I25 -> 0
A26: 2. Затраты подрядчика, в том числе: | B26: =B27 -> 0 | D26: =D27 -> 0 | E26: =E27 -> 76075.739 | F26: =F27 -> 177510.06 | G26: =G27 -> 0 | H26: =H27 -> 207857.21 | I26: =I27 -> 249428.65 | J26: =J27 -> 253585.8 | M26: =SUM(B26:G26)-I26 -> 4157.146 | O26: =12699.227 -> 12699.227
A27: - индексируемые | B27: =B28+B36+B42+B43+B47 -> 0 | D27: =D28+D36+D42+D43+D47 -> 0 | E27: =E28+E36+E42+E43+E47 -> 76075.739 | F27: =F28+F36+F42+F43+F47 -> 177510.06 | G27: =G28+G36+G42+G43+G47 -> 0 | H27: =H28+H36+H42+H43+H47 -> 207857.21 | I27: =I28+I36+I42+I43+I47 -> 249428.65 | J27: =J28+J36+J42+J43+J47 -> 253585.8 | M27: =SUM(B27:G27)-I27 -> 4157.146
A28: Подготовка территории строительства. Всего | B28: =SUM(B30:B35) -> 0 | D28: =SUM(D30:D35) -> 0 | E28: =SUM(E30:E35) -> 13986.14 | F28: =SUM(F30:F35) -> 0 | H28: =SUM(H30:H35) -> 11464.05 | I28: =SUM(I30:I35) -> 13756.859 | J28: =SUM(J30:J35) -> 13986.14 | L28: =Справка!U9 -> 0 | M28: =SUM(B28:G28)-I28 -> 229.281
A29: в том числе: | M29: =SUM(B29:G29)-I29 -> 0
A30: Демонтаж причальных сооружений | E30: =J30 -> 13949.796 | H30: =7693.11+3741.15 -> 11434.26 | I30: =(7693.11+3741.15)*1.2-0.001 -> 13721.111 | J30: =(7693.11+3741.15)*1.22-0.001 -> 13949.796 | K30: =Справка!AA19 -> 1.1445159e+08 | L30: =Справка!W9 -> 116779874 | M30: =SUM(B30:G30)-I30 -> 228.685
A31: Разборка существующих сооружений | E31: =J31 -> 24.449 | H31: 20.04 | I31: =20.04*1.2 -> 24.048 | J31: =20.04*1.22 -> 24.449 | K31: =Справка!W15 -> 1.1445159e+08 | M31: =SUM(B31:G31)-I31 -> 0.401 | O31: 20649782 | P31: =Справка!W9 -> 1.1677987e+08
A32: Восстановление оси трассы | E32: =J32 -> 11.895 | H32: =7.82+1.93 -> 9.75 | I32: =(7.82+1.93)*1.2 -> 11.7 | J32: =(7.82+1.93)*1.22 -> 11.895 | K32: =K30-K31 -> 0 | M32: =SUM(B32:G32)-I32 -> 0.195
E33: =I33-C33-D33 -> 0 | F33: =I33-E33-D33 -> 0 | M33: =SUM(B33:G33)-I33 -> 0
E34: =I34-C34-D34 -> 0 | F34: =I34-E34-D34 -> 0 | M34: =SUM(B34:G34)-I34 -> 0
E35: =I35-C35-D35 -> 0 | F35: =I35-E35-D35 -> 0 | M35: =SUM(B35:G35)-I35 -> 0
A36: Строительно-монтажные работы | E36: 62089.599 | F36: =J36-E36 -> 154810.58 | H36: =173989.15+3797.88 -> 177787.03 | I36: =(173989.15+3797.88)*1.2 -> 213344.44 | J36: =(173989.15+3797.88)*1.22 -> 216900.18 | K36: =K32/1000 -> 0 | M36: =SUM(B36:G36)-I36 -> 3555.741 | O36: =Справка!U9 -> 0
A37: в том числе: | F37: =I37-E37-D37 -> 0 | M37: =SUM(B37:G37)-I37 -> 0
A38: Основные объекты строительства | F38: =I38-E38-D38 -> 632927.98 | I38: =527439.98*1.2 -> 632927.98 | J38: =527439.98*1.2 -> 632927.98 | M38: =SUM(B38:G38)-I38 -> 0
A39: Объекты энергетического хозяйства | F39: =I39-E39-D39 -> 63393.912 | I39: =52828.26*1.2 -> 63393.912 | J39: =52828.26*1.2 -> 63393.912 | M39: =SUM(B39:G39)-I39 -> 0
A40: Наружные сети и сооружения водоснабжения, водоотведения, теплоснабжения и газоснабжения | F40: =I40-E40-D40 -> 205335.3 | I40: =171112.75*1.2 -> 205335.3 | J40: =171112.75*1.2 -> 205335.3 | M40: =SUM(B40:G40)-I40 -> 0
A41: Благоустройство | F41: =I41-E41-D41 -> 2952.6 | I41: =2460.5*1.2 -> 2952.6 | J41: =2460.5*1.2 -> 2952.6 | M41: =SUM(B41:G41)-I41 -> 0
A42: Временные здания и сооружения | D42: =$L$42*(D36+D28) -> 0 | E42: =$L$42*(E36+E28) -> 0 | F42: =$L$42*(F36+F28) -> 0 | L42: =I42/(I36+I28) -> 0 | M42: =SUM(B42:G42)-I42 -> 0
A43: Прочие работы | B43: =SUM(B44:B46) -> 0 | D43: =SUM(D44:D46) -> 0 | E43: =SUM(E44:E46) -> 0 | F43: =SUM(F44:F46) -> 17727.21 | H43: =SUM(H44:H46) -> 14530.5 | I43: =SUM(I44:I46) -> 17436.6 | J43: =SUM(J44:J46) -> 17727.21 | K43: =Справка!AA15-Справка!W15-Справка!Y15 -> 0 | M43: =SUM(B43:G43)-I43 -> 290.61
...

Sheet НМЦК подряд
A1: СОГЛАСОВАНО | E1: УТВЕРЖДАЮ
A2: Заместитель начальника КГКУ "Камчатуправтодор" | E2: Начальник КГКУ "Камчатуправтодор"
A3: ______________А.Л. Нейштадт | E3: ______________О.В.Булах
A4: «____»______________2022 г. | E4: «____»______________2022 г.
A6: Расчет начальной (максимальной) цены контракта
A7: на строительство причальных сооружений через протоку Озерная в Усть-Камчатском районе Камчатского края
A9: Основания для расчета:
A10: 1. Приказ КГКУ "Камчатуправтодор" от 29.07.2022г. №402 Об утверждении проектной документации "Строительство причальных сооружений через протоку Озерная в Усть-Камчатском районе Камчатского края"
A11: 2. Положительное заключение государственной экспертизы проектной документации и результатов инженерных изысканий №41-1-1-2-049246-2022 от 22.07.2022г.
A12: 3. Утвержденный сводный сметный расчет
F13: руб.
A14: Наименование работ и затрат | B14: Стоимость работ в ценах на дату утверждения сметной документации на 2 квартал 2021 года | C14: Индекс фактической инфляции | D14: Стоимость работ в ценах на дату формирования начальной максимальной цены контракта | E14: Индекс прогнозной инфляции на период выполнения работ | F14: Начальная (максимальная) цена контракта с учетом индекса прогнозной инфляции на период выполнения работ
A15: 1 | B15: 2 | C15: 3 | D15: 4 | E15: 5 | F15: 6
A16: Подготовка территории строительства | B16: =Затраты!H28*1000-0.12 -> 11464050 | C16: =Справка!F15 -> 1.399 | D16: =B16*C16 -> 16038206 | E16: =Справка!K15 -> 1.07537 | F16: =ROUND(D16*E16,2) -> 17247005
A17: Строительно-монтажные работы | B17: =Затраты!I36/1.2*1000 -> 177787030 | C17: =$C$16 -> 1.399 | D17: =B17*C17 -> 2.4872405e+08 | E17: =$E$16 -> 1.07537 | F17: =ROUND(D17*E17,2) -> 2.6747039e+08
A18: Перебазировка техники | B18: =Затраты!I44/1.2*1000 -> 3382520 | C18: =$C$16 -> 1.399 | D18: =B18*C18 -> 4732145.5 | E18: =$E$16 -> 1.07537 | F18: =ROUND(D18*E18,2) -> 5088807.3
A19: Командировочные расходы | B19: =Затраты!I46/1.2*1000 -> 2798500 | C19: =$C$16 -> 1.399 | D19: =B19*C19 -> 3915101.5 | E19: =$E$16 -> 1.07537 | F19: =ROUND(D19*E19,2) -> 4210182.7
A20: Доставка основных материалов | B20: =Затраты!I45/1.2*1000 -> 8349480 | C20: =$C$16 -> 1.399 | D20: =B20*C20 -> 11680923 | E20: =$E$16 -> 1.07537 | F20: =ROUND(D20*E20,2) -> 12561314
A21: Резерв на непредвиденные работы и затраты 2% | B21: =(B16+B17+B18+B19+B20)*2% -> 4075631.6 | C21: =$C$16 -> 1.399 | D21: =B21*C21 -> 5701808.6 | E21: =$E$16 -> 1.07537 | F21: =ROUND(D21*E21,2) -> 6131553.9
A22: Стоимость СМР без учета НДС | B22: =SUM(B16:B21) -> 2.0785721e+08 | D22: =SUM(D16:D21) -> 2.9079224e+08 | F22: =SUM(F16:F21) -> 3.1270925e+08
A23: НДС (22%) | B23: =B22*0.22-0.01 -> 45728587 | D23: =D22*22% -> 63974293 | F23: =F22*22% -> 68796035
A24: Итого | B24: =B22+B23 -> 253585798 | D24: =D22+D23 -> 3.5476653e+08 | F24: =F22+F23 -> 3.8150528e+08
B25: =Справка!B14 -> 253585798 | D25: =Справка!H14 -> 354766531
A26: Продолжительность строительства: | B26: =B25-B24 -> 0 | D26: =B24*C22 -> 0 | F26: =Справка!AA14 -> 3.8150528e+08
A27: Начало производства работ - июнь 2026 года
A28: Окончание производства работ - октябрь 2027 года
A29: Уровень цен утвержденной сметной документации - 1 квартал 2022 года
A30: Дата формирования НМЦК - апрель 2026 года
A32: 1. Расчет индексов фактической инфляции с использованием ИПЦ Росстата (Камчатский край):
A34: =Справка!A24 -> март 2023 / март 2022 | B34: 108.6 | C34: =B34/100 -> 1.086
A35: =Справка!A25 -> март 2024 / март 2023 | B35: 109.53 | C35: =B35/100 -> 1.0953
A36: =Справка!A26 -> март 2025 / март 2024 | B36: 106.56 | C36: =B36/100 -> 1.0656
A37: =Справка!A27 -> 45748 | B37: 98.08 | C37: =B37/100 -> 0.9808
A38: =Справка!A28 -> 45778 | B38: 101.17 | C38: =B38/100 -> 1.0117
A39: =Справка!A29 -> 45809 | B39: 103.19 | C39: =B39/100 -> 1.0319
A40: =Справка!A30 -> 45839 | B40: 100.64 | C40: =B40/100 -> 1.0064
A41: =Справка!A31 -> 45870 | B41: 100.15 | C41: =B41/100 -> 1.0015
A42: =Справка!A32 -> 45901 | B42: 102.06 | C42: =B42/100 -> 1.0206
A43: =Справка!A33 -> 45931 | B43: 100.26 | C43: =B43/100 -> 1.0026
A44: =Справка!A34 -> 45962 | B44: 100.86 | C44: =B44/100 -> 1.0086
...

Sheet ССР 
D2: СВОДНЫЙ СМЕТНЫЙ РАСЧЕТ СТОИМОСТИ СТРОИТЕЛЬСТВА
C4: Строитсльство причальных сооружений через протоку Озерная в Усть-Камчатском районе Камчатского края
D5: (наименование стройки)
B7: Составлена в ценах по состоянию на 1 квартал 2022 г.
O8: =(H38)/(H25+H29+H16+H17+H18) -> 0.014787996 | P8: прочие общие
H9: Для расчета | O9: =(H37)/(H24+H28) -> 0.053245327 | P9: прочие левый
A10: № пп | B10: Номера сметных расчетов и смет | C10: Наименование глав, объектов, работ и затрат | D10: Сметная стоимость, тыс. руб. | H10: Общая сметная стоимость, тыс. руб. | I10: Доставка материалов | J10: Прочие | K10: Итого | L10: В ценах контракта | M10: Индекс перехода в цены контракта | O10: =(H36)/(H23+H27) -> 0.040715226 | P10: прочие правый
D11: строитель- ных работ | E11: монтажных работ | F11: оборудования, мебели, инвентаря | G11: прочих
A14: 1 | B14: 2 | C14: 3 | D14: 4 | E14: 5 | F14: 6 | G14: 7 | H14: 8
A15: Глава 1. Подготовка территории строительства
B16: 01-01 | C16: Демонтаж причальных сооружений. Правый берег | D16: 7693.11 | H16: =D16+E16+F16+G16 -> 7693.11 | J16: =H16*$O$8 -> 113.766 | K16: =H16+I16+J16 -> 7806.876 | L16: =K16*Справка!$F$15*Справка!$K$15 -> 11744.997 | M16: =L16/K16 -> 1.5044426
B17: 01-02 | C17: Демонтаж причальных сооружений. Левый берег | D17: 3264.51 | E17: 476.64 | H17: =D17+E17+F17+G17 -> 3741.15 | J17: =H17*$O$8 -> 55.324 | K17: =H17+I17+J17 -> 3796.474 | L17: =K17*Справка!$F$15*Справка!$K$15 -> 5711.577 | M17: =L17/K17 -> 1.5044425
B18: 01-03 | C18: Разборка существующих сооружений | D18: 20.04 | H18: =D18+E18+F18+G18 -> 20.04 | J18: =H18*$O$8 -> 0.296 | K18: =H18+I18+J18 -> 20.336 | L18: =K18*Справка!$F$15*Справка!$K$15 -> 30.594 | M18: =L18/K18 -> 1.5044256
B19: Расчет №1 | C19: Восстановление оси трассы (правый) | G19: 7.82 | H19: =D19+E19+F19+G19 -> 7.82 | K19: =H19+I19+J19 -> 7.82 | L19: =K19*Справка!$F$15*Справка!$K$15 -> 11.765 | M19: =L19/K19 -> 1.5044757
B20: Расчет №2 | C20: Восстановление оси трассы (левый) | G20: 1.93 | H20: =D20+E20+F20+G20 -> 1.93 | K20: =H20+I20+J20 -> 1.93 | L20: =K20*Справка!$F$15*Справка!$K$15 -> 2.904 | M20: =L20/K20 -> 1.5046632
B21: Итого по Главе 1. "Подготовка территории строительства" | D21: =SUM(D16:D20) -> 10977.66 | E21: =SUM(E16:E20) -> 476.64 | F21: =SUM(F16:F20) -> 0 | G21: =SUM(G16:G20) -> 9.75 | H21: =SUM(H16:H20) -> 11464.05 | I21: =SUM(I16:I20) -> 0 | J21: =SUM(J16:J20) -> 169.386 | K21: =SUM(K16:K20) -> 11633.436 | L21: =SUM(L16:L20) -> 17501.837
A22: Глава 2. Основные объекты строительства
B23: 02-01 | C23: Правый берег | D23: 86653.19 | E23: 23.94 | H23: =D23+E23+F23+G23 -> 86677.13 | I23: =H23*O10 -> 3529.079 | J23: =H23*$O$8 -> 1281.781 | K23: =H23+I23+J23 -> 91487.99 | L23: =K23*Справка!$F$15*Справка!$K$15 -> 137638.43 | M23: =L23/K23 -> 1.5044426
B24: 02-02 | C24: Левый берег | D24: 87288.08 | E24: 23.94 | H24: =D24+E24+F24+G24 -> 87312.02 | I24: =H24*O9 -> 4648.957 | J24: =H24*$O$8 -> 1291.17 | K24: =H24+I24+J24 -> 93252.147 | L24: =K24*Справка!$F$15*Справка!$K$15 -> 140292.51 | M24: =L24/K24 -> 1.5044426
B25: Итого по Главе 2. "Основные объекты строительства" | D25: =SUM(D23:D24) -> 173941.27 | E25: =SUM(E23:E24) -> 47.88 | F25: =SUM(F23:F24) -> 0 | G25: =SUM(G23:G24) -> 0 | H25: =SUM(H23:H24) -> 173989.15 | I25: =SUM(I23:I24) -> 8178.036 | J25: =SUM(J23:J24) -> 2572.951 | K25: =SUM(K23:K24) -> 184740.14 | L25: =SUM(L23:L24) -> 277930.94
A26: Глава 4. Объекты энергетического хозяйства
B27: 04-01 | C27: Наружное освещение (правый берег) | D27: 1627.57 | E27: 820.21 | F27: 8.33 | H27: =D27+E27+F27+G27 -> 2456.11 | I27: =H27*O10 -> 100.001 | J27: =H27*$O$8 -> 36.321 | K27: =H27+I27+J27 -> 2592.432 | L27: =K27*Справка!$F$15*Справка!$K$15 -> 3900.165 | M27: =L27/K27 -> 1.5044425
B28: 04-02 | C28: Наружное освещение (левый берег) | D28: 784.57 | E28: 550.82 | F28: 6.38 | H28: =D28+E28+F28+G28 -> 1341.77 | I28: =H28*O9 -> 71.443 | J28: =H28*$O$8 -> 19.842 | K28: =H28+I28+J28 -> 1433.055 | L28: =K28*Справка!$F$15*Справка!$K$15 -> 2155.949 | M28: =L28/K28 -> 1.5044426
B29: Итого по Главе 4. "Объекты энергетического хозяйства" | D29: =SUM(D27:D28) -> 2412.14 | E29: =SUM(E27:E28) -> 1371.03 | F29: =SUM(F27:F28) -> 14.71 | G29: =SUM(G27:G28) -> 0 | H29: =SUM(H27:H28) -> 3797.88 | I29: =SUM(I27:I28) -> 171.444 | J29: =SUM(J27:J28) -> 56.163 | K29: =SUM(K27:K28) -> 4025.487 | L29: =SUM(L27:L28) -> 6056.114
A30: Глава 7. Благоустройство и озеленение территории
B31: Итого по Главам 1-7 | D31: =D29+D25+D21 -> 187331.07 | E31: =E29+E25+E21 -> 1895.55 | F31: =F29+F25+F21 -> 14.71 | G31: =G29+G25+G21 -> 9.75 | H31: =H29+H25+H21 -> 189251.08 | I31: =I29+I25+I21 -> 8349.48 | J31: =J29+J25+J21 -> 2798.5 | K31: =K29+K25+K21 -> 200399.06 | L31: =L29+L25+L21 -> 301488.89
A32: Глава 8. Временные здания и сооружения
B33: Итого по Главам 1-8 | D33: =D31 -> 187331.07 | E33: =E31 -> 1895.55 | F33: =F31 -> 14.71 | G33: =G31 -> 9.75 | H33: =H31 -> 189251.08 | I33: =I31 -> 8349.48 | J33: =J31 -> 2798.5 | K33: =K31 -> 200399.06 | L33: =L31 -> 301488.89
A34: Глава 9. Прочие работы и затраты
B35: 09-01 | C35: Расчет перебазировки техники | G35: 3382.52 | H35: =D35+E35+F35+G35 -> 3382.52 | K35: =H35+I35+J35 -> 3382.52 | L35: =K35*Справка!$F$15*Справка!$K$15 -> 5088.807 | M35: =L35/K35 -> 1.5044425
B36: 09-02 | C36: Расчет стоимости доставки материалов (правый берег) | D36: 3629.08 | H36: =D36+E36+F36+G36 -> 3629.08
B37: 09-03 | C37: Расчет стоимости доставки материалов (левый берег) | D37: 4720.4 | H37: =D37+E37+F37+G37 -> 4720.4
B38: Расчет №3 | C38: Командировочные расходы | G38: 2798.5 | H38: =D38+E38+F38+G38 -> 2798.5
B39: Итого по Главе 9. "Прочие работы и затраты" | D39: =SUM(D35:D38) -> 8349.48 | E39: =SUM(E35:E38) -> 0 | F39: =SUM(F35:F38) -> 0 | G39: =SUM(G35:G38) -> 6181.02 | H39: =SUM(H35:H38) -> 14530.5 | I39: =SUM(I35:I38) -> 0 | J39: =SUM(J35:J38) -> 0 | K39: =SUM(K35:K38) -> 3382.52 | L39: =SUM(L35:L38) -> 5088.807
B40: Итого по Главам 1-9 | D40: =D39+D33 -> 195680.55 | E40: =E39+E33 -> 1895.55 | F40: =F39+F33 -> 14.71 | G40: =G39+G33 -> 6190.77 | H40: =H39+H33 -> 203781.58 | I40: =I39+I33 -> 8349.48 | J40: =J39+J33 -> 2798.5 | K40: =K39+K33 -> 203781.58 | L40: =L39+L33 -> 306577.7
I41: =H36+H37 -> 8349.48 | J41: =H38 -> 2798.5 | K41: =H40 -> 203781.58
C42: Непредвиденные затраты - 1% | H42: ='НМЦК подряд'!B21/1000 -> 4075.63 | K42: =H42+I42+J42 -> 4075.63 | L42: =K42*Справка!$F$15*Справка!$K$15 -> 6131.552
C43: НДС - 20% | H43: =(H40+H42)*20% -> 41571.44 | L43: =(L40+L42)*20% -> 62541.849
B44: Всего по сводному расчету | H44: =H40+H42+H43 -> 249428.65 | L44: =L40+L42+L43 -> 375251.1
H45: =Справка!B14/1000 -> 253585.8 | L45: =Справка!M14/1000 -> 381505.28

Sheet Расчеты 
A1: "Согласовано" | F1: "Утверждаю"
A2: Заместитель начальника КГКУ "Камчатуправтодор" | G2: Начальник КГКУ "Камчатуправтодор"
A3: ______________________Нейштадт А.Л. | G3: ______________________Булах О.В.
A5: Смета контракта
A7: =Справка!B5 -> Строительство причальных сооружений через протоку Озерная в Усть-Камчатском районе Камчатского края
L8: транспортировка, тн
A9: № п/п | B9: Номера сметных расчетов (смет) и подиций в сметных расчетах (сметах), относящиеся к соответсвующим конструктивным решениям (элементам), комплексам (видам) работ | C9: Наименование конструктивных решений (элементов), комплексов (видов) работ | D9: Ед. идм. | E9: Кол-во | F9: Единичная расценка, руб | G9: Общая стоимость, руб | L9: объем, левый берег | M9: объем, правый берег | N9: Цена за ед.
L10: 51.31 | M10: 88.421 | N10: =76.39*17.26+0.31*485*17.26 -> 3913.53 | Q10: Командировочные | R10: Перебазировка | S10: ИТОГО | T10: В ценах НМЦК | U10: =M10*N10 -> 346038.24
A11: 1 | B11: 2 | C11: 3 | D11: 4 | E11: 5 | F11: 6 | G11: 7 | L11: 568.18 | M11: 597.536 | N11: =76.39*17.26+0.31*511*17.26 -> 4052.65 | Q11: ='НМЦК подряд'!B16+'НМЦК подряд'!B17+'НМЦК подряд'!B20 -> 1.9760056e+08 | U11: =M11*N11 -> 2421604.3
A12: Глава 1. Подготовка территории строительства | L12: 4.73 | M12: 6.41 | N12: =76.39*17.26+0.31*511*17.26+2141.78*17.26 -> 41019.77 | Q12: =Q17/Q11 -> 0.014162409 | R12: =R17/Q11 -> 0.017117968 | U12: =M12*N12 -> 262936.73
A13: Раздел 1.1. Восстановление оси трассы
A14: 01.01.1 | B14: Расчет №1 | C14: Восстановление оси трассы (правый берег) | D14: км | E14: 0.335 | F14: =T14/E14 -> 36217.91 | G14: =F14*E14 -> 12133 | H14: =G14-T14 -> 0 | K14: 7820 | O14: =L14+M14+N14 -> 0 | P14: =K14 -> 7820 | Q14: =K14*$Q$12 -> 111 | R14: =K14*$R$12 -> 134 | S14: =P14+Q14+R14 -> 8065 | T14: =S14*'НМЦК подряд'!$C$16*'НМЦК подряд'!$E$16 -> 12133
A15: 01.01.2 | B15: Расчет №2 | C15: Восстановление оси трассы (левый берег) | D15: км | E15: 0.9 | F15: =T15/E15 -> 3326.67 | G15: =F15*E15 -> 2994 | K15: 1930 | O15: =L15+M15+N15 -> 0 | P15: =K15 -> 1930 | Q15: =K15*$Q$12 -> 27 | R15: =K15*$R$12 -> 33 | S15: =P15+Q15+R15 -> 1990 | T15: =S15*'НМЦК подряд'!$C$16*'НМЦК подряд'!$E$16 -> 2994
C16: Итого: раздел 1.1. | G16: =SUM(G14:G15) -> 15127 | K16: =K14+K15 -> 9750 | L16: =L14+L15 -> 0 | M16: =M14+M15 -> 0 | N16: =N14+N15 -> 0 | O16: =O14+O15 -> 0 | P16: =P14+P15 -> 9750 | Q16: =Q14+Q15 -> 138 | R16: =R14+R15 -> 167 | ... U16: =U14+U15 -> 0
A17: Раздел 1.2. Демонтаж конструкций причального сооружения. Правый берег | L17: 96 | M17: 96 | N17: =76.39*17.26+0.31*524*17.26 -> 4122.21 | Q17: ='НМЦК подряд'!B19 -> 2798500 | R17: ='НМЦК подряд'!B18 -> 3382520 | U17: =M17*N17 -> 395732.16
A18: 01.02.1 | B18: ЛСР №01-01, п.1-6 | C18: Демонтаж существующего деревянного причала (правый берег) с погрузкой и транспортировкой на расстояние до 9 км | D18: комплекс | E18: 1 | F18: =T18/E18 -> 5650864 | G18: =F18*E18 -> 5650864 | K18: =2379956+55156+491806+681965+7945+25361 -> 3642189 | O18: =L18+M18+N18 -> 0 | P18: =K18 -> 3642189 | Q18: =K18*$Q$12 -> 51582 | R18: =K18*$R$12 -> 62347 | S18: =P18+Q18+R18 -> 3756118 | T18: =S18*'НМЦК подряд'!$C$16*'НМЦК подряд'!$E$16 -> 5650864
A19: 01.02.2 | B19: ЛСР №01-01, п.7-12 | C19: Демонтаж существующего пирса (правый берег) с погрузкой и транспортировкой на расстояние до 9 км | D19: комплекс | E19: 1 | F19: =T19/E19 -> 6285005 | G19: =F19*E19 -> 6285005 | K19: =1411337+60887+175490+2336974+15798+50430 -> 4050916 | O19: =L19+M19+N19 -> 0 | P19: =K19 -> 4050916 | Q19: =K19*$Q$12 -> 57371 | R19: =K19*$R$12 -> 69343 | S19: =P19+Q19+R19 -> 4177630 | T19: =S19*'НМЦК подряд'!$C$16*'НМЦК подряд'!$E$16 -> 6285005
C20: Итого: раздел 1.2. | G20: =SUM(G18:G19) -> 11935869 | K20: =SUM(K18:K19) -> 7693105 | L20: =SUM(L18:L19) -> 0 | M20: =SUM(M18:M19) -> 0 | N20: =SUM(N18:N19) -> 0 | O20: =SUM(O18:O19) -> 0 | P20: =SUM(P18:P19) -> 7693105 | Q20: =SUM(Q18:Q19) -> 108953 | R20: =SUM(R18:R19) -> 131690 | ... U20: =SUM(U18:U19) -> 0
A21: Раздел 1.3. Демонтаж конструкций причала левого берега. | O21: =L21+M21+N21 -> 0
A22: Раздел 1.3.1 Временный пирс (судно-лихтер) | O22: =L22+M22+N22 -> 0
A23: 01.03.1 | B23: ЛСР №01-02 п.1 | C23: Срезка надстроек, возвышающихся над уровнем воды | D23: м | E23: 750 | F23: =T23/E23 -> 871.52 | G23: =E23*F23 -> 653640 | K23: 421295 | O23: =L23+M23+N23 -> 0 | P23: =K23+L23+M23+N23 -> 421295 | Q23: =P23*$Q$12 -> 5967 | R23: =P23*$R$12 -> 7212 | S23: =P23+Q23+R23 -> 434474 | T23: =S23*'НМЦК подряд'!$C$16*'НМЦК подряд'!$E$16 -> 653641
A24: 01.03.2 | B24: ЛСР №01-02 п.2 | C24: Откачка воды из корпуса судна-лихтера передвижным насосом | D24: м3 | E24: 100 | F24: =T24/E24 -> 140.15 | G24: =E24*F24 -> 14015 | K24: 9033 | O24: =L24+M24+N24 -> 0 | P24: =K24+L24+M24+N24 -> 9033 | Q24: =P24*$Q$12 -> 128 | R24: =P24*$R$12 -> 155 | S24: =P24+Q24+R24 -> 9316 | T24: =S24*'НМЦК подряд'!$C$16*'НМЦК подряд'!$E$16 -> 14015
A25: 01.03.3 | B25: ЛСР №01-02 п.3 | C25: Очистка трюма судна-лихтера от грунта | D25: м3 | E25: 100 | F25: =T25/E25 -> 228.57 | G25: =E25*F25 -> 22857 | K25: 14732 | O25: =L25+M25+N25 -> 0 | P25: =K25+L25+M25+N25 -> 14732 | Q25: =P25*$Q$12 -> 209 | R25: =P25*$R$12 -> 252 | S25: =P25+Q25+R25 -> 15193 | T25: =S25*'НМЦК подряд'!$C$16*'НМЦК подряд'!$E$16 -> 22857
A26: 01.03.4 | B26: ЛСР №01-02 п.4 | C26: Выравнивание берега до пляжного откоса | D26: м3 | E26: 200 | F26: =T26/E26 -> 39.77 | G26: =E26*F26 -> 7954 | K26: 5126 | O26: =L26+M26+N26 -> 0 | P26: =K26+L26+M26+N26 -> 5126 | Q26: =P26*$Q$12 -> 73 | R26: =P26*$R$12 -> 88 | S26: =P26+Q26+R26 -> 5287 | T26: =S26*'НМЦК подряд'!$C$16*'НМЦК подряд'!$E$16 -> 7954
A27: 01.03.5 | B27: ЛСР №01-02 п.5, п.6 | C27: Забивка свай фундамента анкерной опоры | D27: т | E27: 6.57 | F27: =T27/E27 -> 171729.98 | G27: =E27*F27 -> 1128266 | K27: =94460+632749 -> 727209 | O27: =L27+M27+N27 -> 0 | P27: =K27+L27+M27+N27 -> 727209 | Q27: =P27*$Q$12 -> 10299 | R27: =P27*$R$12 -> 12448 | S27: =P27+Q27+R27 -> 749956 | T27: =S27*'НМЦК подряд'!$C$16*'НМЦК подряд'!$E$16 -> 1128266
A28: 01.03.6 | B28: ЛСР №01-02 п.7-9 | C28: Монтаж анкерной опоры в виде ростверка | D28: м3 | E28: 12 | F28: =T28/E28 -> 28581.75 | G28: =E28*F28 -> 342981 | K28: =86744+129727+4593 -> 221064 | O28: =L28+M28+N28 -> 0 | P28: =K28+L28+M28+N28 -> 221064 | Q28: =P28*$Q$12 -> 3131 | R28: =P28*$R$12 -> 3784 | S28: =P28+Q28+R28 -> 227979 | T28: =S28*'НМЦК подряд'!$C$16*'НМЦК подряд'!$E$16 -> 342981
A29: 01.03.7 | B29: ЛСР №01-02 п.10 | C29: Откачка воды из трюма лихтера | D29: м3 | E29: 200 | F29: =T29/E29 -> 140.13 | G29: =E29*F29 -> 28026 | K29: =18064 -> 18064 | O29: =L29+M29+N29 -> 0 | P29: =K29+L29+M29+N29 -> 18064 | Q29: =P29*$Q$12 -> 256 | R29: =P29*$R$12 -> 309 | S29: =P29+Q29+R29 -> 18629 | T29: =S29*'НМЦК подряд'!$C$16*'НМЦК подряд'!$E$16 -> 28026
A30: 01.03.8 | B30: ЛСР №01-02 п.11-12 | C30: Вытаскивание корпуса судна-лихтера на берег | D30: т | E30: 100 | F30: =T30/E30 -> 8086.47 | G30: =E30*F30 -> 808647 | K30: =512711+8492 -> 521203 | O30: =L30+M30+N30 -> 0 | P30: =K30+L30+M30+N30 -> 521203 | Q30: =P30*$Q$12 -> 7381 | R30: =P30*$R$12 -> 8922 | S30: =P30+Q30+R30 -> 537506 | T30: =S30*'НМЦК подряд'!$C$16*'НМЦК подряд'!$E$16 -> 808647
A31: 01.03.10 | B31: ЛСР №01-02 п.13 | C31: Демонтаж анкерных опор в виде ростверка | D31: м3 | E31: 12 | F31: =T31/E31 -> 146671.75 | G31: =E31*F31 -> 1760061 | K31: 1134424 | O31: =L31+M31+N31 -> 0 | P31: =K31+L31+M31+N31 -> 1134424 | Q31: =P31*$Q$12 -> 16066 | R31: =P31*$R$12 -> 19419 | S31: =P31+Q31+R31 -> 1169909 | T31: =S31*'НМЦК подряд'!$C$16*'НМЦК подряд'!$E$16 -> 1760061
A32: 01.03.11 | B32: ЛСР №01-02 п.14 | C32: Демонтаж свай | D32: т | E32: 6.57 | F32: =T32/E32 -> 27220.55 | G32: =E32*F32 -> 178839.01 | K32: 115269 | O32: =L32+M32+N32 -> 0 | P32: =K32+L32+M32+N32 -> 115269 | Q32: =P32*$Q$12 -> 1632 | R32: =P32*$R$12 -> 1973 | S32: =P32+Q32+R32 -> 118874 | T32: =S32*'НМЦК подряд'!$C$16*'НМЦК подряд'!$E$16 -> 178839
A33: 01.03.12 | B33: ЛСР №01-02 п.15 | C33: Перевозка автосамосвалами металлолома на расстояние до 10 км | D33: т | E33: 150 | F33: =T33/E33 -> 280.38 | G33: =E33*F33 -> 42057 | K33: 27107 | O33: =L33+M33+N33 -> 0 | P33: =K33+L33+M33+N33 -> 27107 | Q33: =P33*$Q$12 -> 384 | R33: =P33*$R$12 -> 464 | S33: =P33+Q33+R33 -> 27955 | T33: =S33*'НМЦК подряд'!$C$16*'НМЦК подряд'!$E$16 -> 42057
C34: Итого по Разделу 1.3.1 | G34: =SUM(G23:G33) -> 4987343 | K34: =SUM(K23:K33) -> 3214526 | L34: =SUM(L23:L33) -> 0 | M34: =SUM(M23:M33) -> 0 | N34: =SUM(N23:N33) -> 0 | O34: =SUM(O23:O33) -> 0 | P34: =SUM(P23:P33) -> 3214526 | Q34: =SUM(Q23:Q33) -> 45526 | R34: =SUM(R23:R33) -> 55026 | ... U34: =SUM(U23:U33) -> 0
A35: Раздел 1.3.2 Временный причал (плашкоут) | O35: =L35+M35+N35 -> 0 | P35: =K35+L35+M35+N35 -> 0 | Q35: =P35*$Q$12 -> 0 | R35: =P35*$R$12 -> 0 | S35: =K35+Q35+R35 -> 0 | T35: =S35*'НМЦК подряд'!$C$16*'НМЦК подряд'!$E$16 -> 0
A36: 14 | B36: ЛСР №01-02 п.16 | C36: Очистка корпуса плашкоута от грунта экскаватором | D36: м3 | E36: 200 | F36: =T36/E36 -> 157.66 | G36: =E36*F36 -> 31532 | K36: 20323 | O36: =L36+M36+N36 -> 0 | P36: =K36+L36+M36+N36 -> 20323 | Q36: =P36*$Q$12 -> 288 | R36: =P36*$R$12 -> 348 | S36: =P36+Q36+R36 -> 20959 | T36: =S36*'НМЦК подряд'!$C$16*'НМЦК подряд'!$E$16 -> 31532
A37: 01.03.13 | B37: ЛСР №01-02 п.17 | C37: Откачка воды из корпуса плашкоута насосами | D37: т | E37: 100 | F37: =T37/E37 -> 140.15 | G37: =E37*F37 -> 14015 | K37: 9033 | O37: =L37+M37+N37 -> 0 | P37: =K37+L37+M37+N37 -> 9033 | Q37: =P37*$Q$12 -> 128 | R37: =P37*$R$12 -> 155 | S37: =P37+Q37+R37 -> 9316 | T37: =S37*'НМЦК подряд'!$C$16*'НМЦК подряд'!$E$16 -> 14015
A38: 01.03.14 | B38: ЛСР №01-02 п.18-19 | C38: Вытаскивание корпуса плашкоута на берег | D38: т | E38: 50 | F38: =T38/E38 -> 14942.1 | G38: =E38*F38 -> 747105 | K38: =476635+4901 -> 481536 | O38: =L38+M38+N38 -> 0 | P38: =K38+L38+M38+N38 -> 481536 | Q38: =P38*$Q$12 -> 6820 | R38: =P38*$R$12 -> 8243 | S38: =P38+Q38+R38 -> 496599 | T38: =S38*'НМЦК подряд'!$C$16*'НМЦК подряд'!$E$16 -> 747105
A39: 01.03.15 | B39: ЛСР №01-02 п.20 | C39: Перевозка автосамосвалами металлолома на расстояние до 10 км | D39: т | E39: 87 | F39: =T39/E39 -> 280.38 | G39: =E39*F39 -> 24393.06 | K39: =15722 -> 15722 | O39: =L39+M39+N39 -> 0 | P39: =K39+L39+M39+N39 -> 15722 | Q39: =P39*$Q$12 -> 223 | R39: =P39*$R$12 -> 269 | S39: =P39+Q39+R39 -> 16214 | T39: =S39*'НМЦК подряд'!$C$16*'НМЦК подряд'!$E$16 -> 24393
C40: Итого по Разделу 1.3.2 | G40: =SUM(G36:G39) -> 817045.06 | K40: =SUM(K36:K39) -> 526614 | L40: =SUM(L36:L39) -> 0 | M40: =SUM(M36:M39) -> 0 | N40: =SUM(N36:N39) -> 0 | O40: =L40+M40+N40 -> 0 | P40: =SUM(P36:P39) -> 526614 | Q40: =SUM(Q36:Q39) -> 7459 | R40: =SUM(R36:R39) -> 9015 | S40: =P40+Q40+R40 -> 543088 | T40: =SUM(T36:T39) -> 817045
C41: Итого по Разделу 1.3. | G41: =G40+G34 -> 5804388 | K41: =K40+K34 -> 3741140 | L41: =L40+L34 -> 0 | M41: =M40+M34 -> 0 | N41: =N40+N34 -> 0 | O41: =O40+O34 -> 0 | P41: =P40+P34 -> 3741140 | Q41: =Q40+Q34 -> 52985 | R41: =R40+R34 -> 64041 | ... U41: =U40+U34 -> 0
A42: Раздел 1.4. Демонтаж существущего обустройства | O42: =L42+M42+N42 -> 0 | P42: =K42+L42+M42+N42 -> 0 | Q42: =P42*$Q$12 -> 0 | R42: =P42*$R$12 -> 0 | S42: =K42+Q42+R42 -> 0 | T42: =S42*'НМЦК подряд'!$C$16*'НМЦК подряд'!$E$16 -> 0
...

Sheet Проект сметы 
E1: "Утверждаю"
F2: Начальник КГКУ "Камчатуправтодор"
F3: ______________________Щегловский В.С.
A5: Проект Сметы контракта
A7: =Справка!B5 -> Строительство причальных сооружений через протоку Озерная в Усть-Камчатском районе Камчатского края
A9: № п/п | B9: Наименование конструктивных решений (элементов), комплексов (видов) работ | C9: Ед. идм. | D9: Кол-во | E9: Единичная расценка, руб | F9: Общая стоимость, руб
A11: 1 | B11: 3 | C11: 4 | D11: 5 | E11: 6 | F11: 7
A12: Глава 1. Подготовка территории строительства
A13: Раздел 1.1. Восстановление оси трассы
A14: 01.01.1 | B14: Восстановление оси трассы (правый берег) | C14: км | D14: 0.335 | E14: 36217.91 | F14: =E14*D14 -> 12133
A15: 01.01.2 | B15: Восстановление оси трассы (левый берег) | C15: км | D15: 0.9 | E15: 3326.67 | F15: =E15*D15 -> 2994
B16: Итого: раздел 1.1. | F16: =SUM(F14:F15) -> 15127
A17: Раздел 1.2. Демонтаж конструкций причального сооружения. Правый берег
A18: 01.02.1 | B18: Демонтаж существующего деревянного причала (правый берег) с погрузкой и транспортировкой на расстояние до 9 км | C18: комплекс | D18: 1 | E18: 5650864 | F18: =E18*D18 -> 5650864
A19: 01.02.2 | B19: Демонтаж существующего пирса (правый берег) с погрузкой и транспортировкой на расстояние до 9 км | C19: комплекс | D19: 1 | E19: 6285005 | F19: =E19*D19 -> 6285005
B20: Итого: раздел 1.2. | F20: =SUM(F18:F19) -> 11935869
A21: Раздел 1.3. Демонтаж конструкций причала левого берега.
A22: Раздел 1.3.1 Временный пирс (судно-лихтер)
A23: 01.03.1 | B23: Срезка надстроек, возвышающихся над уровнем воды | C23: м | D23: 750 | E23: 871.52 | F23: =D23*E23 -> 653640
A24: 01.03.2 | B24: Откачка воды из корпуса судна-лихтера передвижным насосом | C24: м3 | D24: 100 | E24: 140.15 | F24: =D24*E24 -> 14015
A25: 01.03.3 | B25: Очистка трюма судна-лихтера от грунта | C25: м3 | D25: 100 | E25: 228.57 | F25: =D25*E25 -> 22857
A26: 01.03.4 | B26: Выравнивание берега до пляжного откоса | C26: м3 | D26: 200 | E26: 39.77 | F26: =D26*E26 -> 7954
A27: 01.03.5 | B27: Забивка свай фундамента анкерной опоры | C27: т | D27: 6.57 | E27: 171729.98 | F27: =D27*E27 -> 1128266
A28: 01.03.6 | B28: Монтаж анкерной опоры в виде ростверка | C28: м3 | D28: 12 | E28: 28581.75 | F28: =D28*E28 -> 342981
A29: 01.03.7 | B29: Откачка воды из трюма лихтера | C29: м3 | D29: 200 | E29: 140.13 | F29: =D29*E29 -> 28026
A30: 01.03.8 | B30: Вытаскивание корпуса судна-лихтера на берег | C30: т | D30: 100 | E30: 8086.47 | F30: =D30*E30 -> 808647
A31: 01.03.9 | B31: Демонтаж анкерных опор в виде ростверка | C31: м3 | D31: 12 | E31: 146671.75 | F31: =D31*E31 -> 1760061
A32: 01.03.10 | B32: Демонтаж свай | C32: т | D32: 6.57 | E32: 27220.55 | F32: =D32*E32 -> 178839.01
A33: 01.03.11 | B33: Перевозка автосамосвалами металлолома на расстояние до 10 км | C33: т | D33: 150 | E33: 280.38 | F33: =D33*E33 -> 42057
B34: Итого по Разделу 1.3.1 | F34: =SUM(F23:F33) -> 4987343
A35: Раздел 1.3.2 Временный причал (плашкоут)
A36: 01.03.12 | B36: Очистка корпуса плашкоута от грунта экскаватором | C36: м3 | D36: 200 | E36: 157.66 | F36: =D36*E36 -> 31532
A37: 01.03.13 | B37: Откачка воды из корпуса плашкоута насосами | C37: т | D37: 100 | E37: 140.15 | F37: =D37*E37 -> 14015
A38: 01.03.14 | B38: Вытаскивание корпуса плашкоута на берег | C38: т | D38: 50 | E38: 14942.1 | F38: =D38*E38 -> 747105
A39: 01.03.15 | B39: Перевозка автосамосвалами металлолома на расстояние до 10 км | C39: т | D39: 87 | E39: 280.38 | F39: =D39*E39 -> 24393.06
B40: Итого по Разделу 1.3.2 | F40: =SUM(F36:F39) -> 817045.06
B41: Итого по Разделу 1.3. | F41: =F40+F34 -> 5804388
A42: Раздел 1.4. Демонтаж существущего обустройства
A43: 01.04.1 | B43: Демонтаж дорожных знаков на металлических стойках с транспортировкой на полигон ТБО на расстояние до 9 км | C43: шт | D43: 4 | E43: 7771.5 | F43: =E43*D43 -> 31086
B44: Итого: раздел 1.4. | F44: =F43 -> 31086
...

Sheet Ведомость объемов
D1: УТВЕРЖДАЮ
C2: Начальник КГКУ "Камчатуправтодор"
C3: ______________В.С. Щегловский
C4: «___»______________2026 г.
A6: Ведомость объемов конструктивных решений (элементов) и комплексов (видов) работ, оборудования
A7: Строительство причальных сооружений через протоку Озерная в Усть-Камчатском районе Камчатского края
A8: (наименование объекта)
A9: № п/п | B9: Номера сметных расчетов (смет) и подиций в сметных расчетах (сметах), относящиеся к соответсвующим конструктивным решениям (элементам), комплексам (видам) работ | C9: Наименование конструктивных решений (элементов), комплексов (видов) работ | D9: Ед. идм. | E9: Кол-во
A11: 1 | B11: 2 | C11: 3 | D11: 4 | E11: 5
A12: Глава 1. Подготовка территории строительства
A13: Раздел 1.1. Восстановление оси трассы
A14: 01.01.1 | B14: Расчет №1 | C14: Восстановление оси трассы (правый берег) | D14: км | E14: 0.335
A15: 01.01.2 | B15: Расчет №2 | C15: Восстановление оси трассы (левый берег) | D15: км | E15: 0.9
A16: Раздел 1.2. Демонтаж конструкций причального сооружения. Правый берег
A17: 01.02.1 | B17: ЛСР №01-01, п.1-6 | C17: Демонтаж существующего деревянного причала (правый берег) с погрузкой и транспортировкой на расстояние до 9 км | D17: комплекс | E17: 1
A18: 01.02.2 | B18: ЛСР №01-01, п.7-12 | C18: Демонтаж существующего пирса (правый берег) с погрузкой и транспортировкой на расстояние до 9 км | D18: комплекс | E18: 1
A19: Раздел 1.3. Демонтаж конструкций причала левого берега.
A20: Раздел 1.3.1 Временный пирс (судно-лихтер)
A21: 01.03.1 | B21: ЛСР №01-02 п.1 | C21: Срезка надстроек, возвышающихся над уровнем воды | D21: м | E21: 750
A22: 01.03.2 | B22: ЛСР №01-02 п.2 | C22: Откачка воды из корпуса судна-лихтера передвижным насосом | D22: м3 | E22: 100
A23: 01.03.3 | B23: ЛСР №01-02 п.3 | C23: Очистка трюма судна-лихтера от грунта | D23: м3 | E23: 100
A24: 01.03.4 | B24: ЛСР №01-02 п.4 | C24: Выравнивание берега до пляжного откоса | D24: м3 | E24: 200
A25: 01.03.5 | B25: ЛСР №01-02 п.5, п.6 | C25: Забивка свай фундамента анкерной опоры | D25: т | E25: 6.57
A26: 01.03.6 | B26: ЛСР №01-02 п.7-9 | C26: Монтаж анкерной опоры в виде ростверка | D26: м3 | E26: 12
A27: 01.03.7 | B27: ЛСР №01-02 п.10 | C27: Откачка воды из трюма лихтера | D27: м3 | E27: 200
A28: 01.03.8 | B28: ЛСР №01-02 п.11-12 | C28: Вытаскивание корпуса судна-лихтера на берег | D28: т | E28: 100
A29: 01.03.10 | B29: ЛСР №01-02 п.13 | C29: Демонтаж анкерных опор в виде ростверка | D29: м3 | E29: 12
A30: 01.03.11 | B30: ЛСР №01-02 п.14 | C30: Демонтаж свай | D30: т | E30: 6.57
A31: 01.03.12 | B31: ЛСР №01-02 п.15 | C31: Перевозка автосамосвалами металлолома на расстояние до 10 км | D31: т | E31: 150
A32: Раздел 1.3.2 Временный причал (плашкоут)
A33: 14 | B33: ЛСР №01-02 п.16 | C33: Очистка корпуса плашкоута от грунта экскаватором | D33: м3 | E33: 200
A34: 01.03.13 | B34: ЛСР №01-02 п.17 | C34: Откачка воды из корпуса плашкоута насосами | D34: т | E34: 100
A35: 01.03.14 | B35: ЛСР №01-02 п.18-19 | C35: Вытаскивание корпуса плашкоута на берег | D35: т | E35: 50
A36: 01.03.15 | B36: ЛСР №01-02 п.20 | C36: Перевозка автосамосвалами металлолома на расстояние до 10 км | D36: т | E36: 87
A37: Раздел 1.4. Демонтаж существущего обустройства
A38: 01.04.1 | B38: ЛСР №01-03, п.1-2 | C38: Демонтаж дорожных знаков на металлических стойках с транспортировкой на полигон ТБО на расстояние до 9 км | D38: шт | E38: 4
A39: Глава 2. Причальное сооружение (правый берег)
A40: Раздел 2.1. Конструктивные элементы (правый берег)
C41: Причал
A42: 02.01.1 | B42: ЛСР №02-01-01, п. 1 | C42: Погружение вертикальных свай С-1 | D42: тн | E42: 23.81
...

Sheet НМЦК СК
O1: УТВЕРЖДАЮ
O2: Начальник КГКУ "Камчатуправтодор"
O3: ______________О.В. Булах
O4: «____»______________2022 г.
A6: Расчет начальной (максимальной) цены контракта
A7: на оказание услуг по осуществлению строительного контроля за объектом: "Строитсльство причальных сооружений через протоку Озерная в Усть-Камчатском районе Камчатского края"
A8: Основания для расчета:
A9: ='НМЦК подряд'!A10:F10 -> 1. Приказ КГКУ "Камчатуправтодор" от 29.07.2022г. №402 Об утверждении проектной документации "Строительство причальных сооружений через протоку Озерная в Усть-Камчатском районе Камчатского края"
A10: ='НМЦК подряд'!A11:F11 -> 2. Положительное заключение государственной экспертизы проектной документации и результатов инженерных изысканий №41-1-1-2-049246-2022 от 22.07.2022г.
A11: 3. Утвержденный сводный сметный расчет
Q12: руб.
A13: Наименование работ и затрат | B13: Стоимость работ в ценах на дату утверждения сметной документации / 1 квартал 2022 года | C13: Индекс фактической инфляции | D13: Стоимость работ в ценах на дату формирования начальной (максимальной) цены контракта | F13: Индекс прогнозной инфляции на период выполнения работ | H13: Начальная (максимальная) цена контракта с учетом индекса прогнозной инфляции на период выполнения работ | L13: Распределение по годам (в ценах 1 квартала 2022 года) | O13: Распределение по годам (с учетом индексов фактической и прогнозной инфляции)
L14: 2025 | M14: 2026 | N14: 2027 | O14: 2025 | P14: 2026 | Q14: 2027
A15: 1 | B15: 2 | C15: 3 | D15: 4 | F15: 5 | H15: 6 | L15: 7 | M15: 8 | N15: 9 | O15: 10 | P15: 11 | Q15: 12
A16: Затраты на осуществление строительного контроля предусмотренные проектно-сметной документацией (2,14%) | B16: =Затраты!I16*1000/1.2 -> 4228440 | C16: =C34 -> 1.3062 | D16: =B16*C16 -> 5523188 | F16: =H61 -> 0 | H16: =D16*F16 -> 0 | L16: =B16*D49 -> 0 | M16: =B16*D50 -> 2306403 | N16: =B16*D51 -> 1922037 | O16: =H16*D49 -> 0 | P16: =H16*D50 -> 0 | Q16: =H16*D51 -> 0
A17: НДС (20%) | B17: =B16*20% -> 845688 | D17: =D16*20% -> 1104638 | H17: =H16*20% -> 0 | L17: =L16*20% -> 0 | M17: =M16*20% -> 461281 | N17: =N16*20% -> 384407 | O17: =O16*20% -> 0 | P17: =P16*20% -> 0 | Q17: =Q16*20% -> 0
A18: Стоимость с учетом НДС | B18: =B16+B17 -> 5074128 | D18: =SUM(D16:E17) -> 6627826 | H18: =SUM(H16:K17) -> 0 | L18: =L16+L17 -> 0 | M18: =M16+M17 -> 2767684 | N18: =N16+N17 -> 2306444 | O18: =O16+O17 -> 0 | P18: =P16+P17 -> 0 | Q18: =Q16+Q17 -> 0
A19: *В зависимости от года утверждения ПСД и планируемого выполнения работ по годам исполнения государственного контракта таблица может быть откорректирована.
A21: Дата формирования НМЦК - | B21: ноябрь 2022 года
A22: Начало оказания услуг - апрель 2023 года
A23: Окончание оказания услуг - ноябрь 2024 года
A25: 1. Расчет индекса фактической инфляции с использованием ИПЦ Росстата (Камчатский край):
A27: =Справка!A24 -> март 2023 / март 2022 | B27: =Справка!B24 -> 108.6 | C27: =B27/100 -> 1.086
A28: =Справка!A25 -> март 2024 / март 2023 | B28: =Справка!B25 -> 109.53 | C28: =B28/100 -> 1.0953
A29: =Справка!A26 -> март 2025 / март 2024 | B29: =Справка!B26 -> 106.56 | C29: =B29/100 -> 1.0656
A30: =Справка!A27 -> 45748 | B30: =Справка!B27 -> 98.08 | C30: =B30/100 -> 0.9808
A31: =Справка!A28 -> 45778 | B31: =Справка!B28 -> 101.17 | C31: =B31/100 -> 1.0117
A32: =Справка!A29 -> 45809 | B32: =Справка!B29 -> 103.19 | C32: =B32/100 -> 1.0319
A33: =Справка!A30 -> 45839 | B33: =Справка!B30 -> 100.64 | C33: =B33/100 -> 1.0064
B34: Индекс фактической инфляции | C34: =C27*C28*C29*C30*C31*C32*C33 -> 1.3062
A36: 2. Расчет индекса прогнозной инфляции (Прогноз социально-экономического развития Камчатского края на 2023-2025 гг. от 06.07.2022г., отрасль "Инвестиции в основной капитал"):
A39: 2025 = | G39: 12 | H39: √ | I39: =B40 -> 0 | J39: = | K39: =I39^(1/G39) -> 0
B40: =Справка!F26 -> 0 | C40: Ежемесячный индекс прогноз на 2025 =
A42: 2026 = | G42: 12 | H42: √ | I42: =B43 -> 1.078 | J42: = | K42: =I42^(1/G42) -> 1.0063
B43: =Справка!F41 -> 1.078 | C43: Ежемесячный индекс прогноз на 2026 =
A45: 2027 = | G45: 12 | H45: √ | I45: =B46 -> 1.077 | J45: = | K45: =I45^(1/G45) -> 1.0062
B46: =Справка!F44 -> 1.077 | C46: Ежемесячный индекс прогноз на 2027 =
A49: Доля сметной стоимости подлежащая выполнению в 2025 году - | D49: =ROUND(F49/(F49+F50+F51),5) -> 0 | F49: 0 | G49: мес.
A50: Доля сметной стоимости подлежащая выполнению в 2026 году - | D50: =ROUND(F50/(F50+F51+F49),5) -> 0.54545 | F50: 12 | G50: мес.
A51: Доля сметной стоимости подлежащая выполнению в 2027 году - | D51: =ROUND(F51/(F51+F50+F49),5) -> 0.45455 | F51: 10 | G51: мес.
...

Sheet НМЦК АН
O1: УТВЕРЖДАЮ
O2: И.о. начальника КГКУ "Камчатуправтодор"
O3: ______________А.Л. Нейштадт
O4: «____»______________2022 г.
A6: Расчет начальной (максимальной) цены контракта
A7: на оказание услуг по осуществлению авторского надзора за объектом: "Строитсльство причальных сооружений через протоку Озерная в Усть-Камчатском районе Камчатского края"
A8: Основания для расчета:
A9: ='НМЦК подряд'!A10:F10 -> 1. Приказ КГКУ "Камчатуправтодор" от 29.07.2022г. №402 Об утверждении проектной документации "Строительство причальных сооружений через протоку Озерная в Усть-Камчатском районе Камчатского края"
A10: ='НМЦК подряд'!A11:F11 -> 2. Положительное заключение государственной экспертизы проектной документации и результатов инженерных изысканий №41-1-1-2-049246-2022 от 22.07.2022г.
A11: 3. Утвержденный сводный сметный расчет
Q12: руб.
A13: Наименование работ и затрат | B13: Стоимость работ в ценах на дату утверждения сметной документации / 1 квартал 2022 года | C13: Индекс фактической инфляции | D13: Стоимость работ в ценах на дату формирования начальной (максимальной) цены контракта | F13: Индекс прогнозной инфляции на период выполнения работ | H13: Начальная (максимальная) цена контракта с учетом индекса прогнозной инфляции на период выполнения работ | L13: Распределение по годам (в ценах 1 квартала 2022 года) | O13: Распределение по годам (с учетом индексов фактической и прогнозной инфляции)
L14: 2022 | M14: 2023 | N14: 2024 | O14: 2022 | P14: 2023 | Q14: 2024
A15: 1 | B15: 2 | C15: 3 | D15: 4 | F15: 5 | H15: 6 | L15: 7 | M15: 8 | N15: 9 | O15: 10 | P15: 11 | Q15: 12
A16: Затраты на осуществление авторского надзора предусмотренные проектно-сметной документацией (0,2%) | B16: 408681 | C16: =C35 -> 1.3062 | D16: =B16*C16 -> 533819 | F16: =H62 -> 0 | H16: =D16*F16 -> 0 | L16: 0 | M16: =B16*D51 -> 0 | N16: =B16*D52+1 -> 408682 | O16: =H16*D50 -> 0 | P16: =H16*D51 -> 0 | Q16: =H16*D52 -> 0
A17: НДС (20%) | B17: =B16*0.22 -> 89910 | D17: =D16*0.22 -> 117440 | M17: =M16*0.22 -> 0 | N17: =N16*0.22 -> 89910
A18: Стоимость с учетом НДС | B18: =B16*1.22 -> 498591 | D18: =D16+D17 -> 651259 | H18: =SUM(H16:K17) -> 0 | L18: =L16+L17 -> 0 | M18: =M16+M17 -> 0 | N18: =N16+N17 -> 498592 | O18: =O16+O17 -> 0 | P18: =P16+P17 -> 0 | Q18: =Q16+Q17 -> 0
A19: *В зависимости от года утверждения ПСД и планируемого выполнения работ по годам исполнения государственного контракта таблица может быть откорректирована.
A21: Дата формирования НМЦК - | B21: октябрь 2022 года
A22: Начало оказания услуг - ноябрь 2022 года
A23: Окончание оказания услуг - ноябрь 2024 года
A25: 1. Расчет индекса фактической инфляции с использованием ИПЦ Росстата (Камчатский край):
A27: ='НМЦК СК'!A27 -> март 2023 / март 2022 | B27: ='НМЦК СК'!B27 -> 108.6 | C27: =B27/100 -> 1.086
A28: ='НМЦК СК'!A28 -> март 2024 / март 2023 | B28: ='НМЦК СК'!B28 -> 109.53 | C28: =B28/100 -> 1.0953
A29: ='НМЦК СК'!A29 -> март 2025 / март 2024 | B29: ='НМЦК СК'!B29 -> 106.56 | C29: =B29/100 -> 1.0656
A30: ='НМЦК СК'!A30 -> 45748 | B30: ='НМЦК СК'!B30 -> 98.08 | C30: =B30/100 -> 0.9808
A31: ='НМЦК СК'!A31 -> 45778 | B31: ='НМЦК СК'!B31 -> 101.17 | C31: =B31/100 -> 1.0117
A32: ='НМЦК СК'!A32 -> 45809 | B32: ='НМЦК СК'!B32 -> 103.19 | C32: =B32/100 -> 1.0319
A33: ='НМЦК СК'!A33 -> 45839 | B33: ='НМЦК СК'!B33 -> 100.64 | C33: =B33/100 -> 1.0064
B35: Индекс фактической инфляции | C35: =C27*C28*C29*C30*C31*C32*C33 -> 1.3062
A37: 2. Расчет индекса прогнозной инфляции (Прогноз социально-экономического развития Камчатского края на 2023-2025 гг. от 06.07.2022г., отрасль "Инвестиции в основной капитал"):
A40: 2022 = | G40: 12 | H40: √ | I40: =B41 -> 0 | J40: = | K40: =I40^(1/G40) -> 0
B41: =Справка!F26 -> 0 | C41: Ежемесячный индекс прогноз на 2022 =
A43: 2023 = | G43: 12 | H43: √ | I43: =B44 -> 1.078 | J43: = | K43: =I43^(1/G43) -> 1.0063
B44: =Справка!F41 -> 1.078 | C44: Ежемесячный индекс прогноз на 2023 =
A46: 2024 = | G46: 12 | H46: √ | I46: =B47 -> 1.077 | J46: = | K46: =I46^(1/G46) -> 1.0062
B47: =Справка!F44 -> 1.077 | C47: Ежемесячный индекс прогноз на 2024 =
A50: Доля сметной стоимости подлежащая выполнению в 2022 году - | D50: =ROUND(F50/(F50+F51+F52),5) -> 0 | F50: 0 | G50: мес.
A51: Доля сметной стоимости подлежащая выполнению в 2023 году - | D51: 0 | F51: 2 | G51: мес.
A52: Доля сметной стоимости подлежащая выполнению в 2024 году - | D52: 1 | F52: 2 | G52: мес.
...
