Workbook

Sheet 120р медная труба, мкэш, теплои
A1: Министерство | L1: ПАО «Газпром» | AH1: Форма №3.3
A2: Объединение, трест | M2: АО "Газстройпроект" | AH2: Основание: ВСН 012-88 (Часть II)
A3: Участок: | F3: I.II | I3: этап | AN3: Миннефтегазстрой
AH4: Строительство: Аэропортовый комплекс на аэродроме «Левашово»
AH5: Объект: Аэропортовый комплекс на аэродроме «Левашово»
AH6: I этап. Сектор Гражданской авиации (создание технической возможности эксплуатации гражданских судов по МК-258)
AH8: Этап I.II.
Z9: АКТ № | AF9: АИР 1.2-61.17-ОВ3/120р
A10: о результатах проверки изделий/материалов
A12: Медная труба: Ø6,35; Ø9,52; Ø12,70; Ø15,88; Ø28,58;
A13: Кабель монтажный экранированный МКЭШ 3х0,75;
A14: Кабель ВВГнг(А)-LS 5х1,5;
A15: Труба ПВХ гофрированная d20
A16: Изделия теплоизоляционные на основе вспененного синтетического каучука Unionflex STD, толщина 9 мм ООО «Юнион
A17: Полимер Технолоджи»: для труб Ø6,35 09х006, для труб Ø9,52 09х010, для труб Ø12,70 09х012, для труб Ø15,88 09х018,
A18: для труб Ø28,58 09х028
A20: на соответствие техдокументации
AA21: от | AE21: 45337 | BW21: =AE21 -> 45337
A22: Составлен представителями:
A23: строительной организации | S23: =VLOOKUP(BJ23,подписанты!$B$3:$C$11,2,FALSE) -> Ведущий инженер МТО АО «Газстройпроект» | BJ23: Журавлев Ю.С.
T24: (должность, организация, фамилия, инициалы)
A25: службы контроля качества | S25: =VLOOKUP(BJ25,подписанты!$B$3:$C$11,2,FALSE) -> Инженер отдела технического надзора АО «Газстройпроект» | BJ25: Халыгов Э. А.
T26: (должность, организация, фамилия, инициалы)
A27: заказчика | S27: =VLOOKUP(BJ27,подписанты!$B$3:$C$11,2,FALSE) -> Начальник отдела организации и контроля материально-технического обеспечения Управления по реализации проектов авиационной инфраструктуры ГГС | BJ27: Тюкин Е.В.
T28: (должность, организация, фамилия, инициалы)
A29: в том, что произведен | O29: сплошной | BQ29: осмотр | BY29: Конструкив - сплошной вне зависимости объёма материала Выборочный при больших партиях (труб, штукатурки и т.д.), остальное сплошной
E30: (сплошной, выборочный )
A31: Труба медная бесшовная: Ø6,35 - 39,6 м; Ø9,52 - 45,9 м; Ø12,70 - 39,6 м; Ø15,88 - 53,8 м; Ø28,58 - 8,4 м;
A32: Кабель монтажный экранированный МКЭШ - 120 м;
A33: Кабель ВВГнг(А)-LS - 10 м;
A34: Труба ПВХ гофрированная - 130 м;
A35: Изделия теплоизоляционные на основе вспененного синтетического каучука Unionflex STD, толщина 9 мм ООО «Юнион
A36: Полимер Технолоджи»: для труб Ø6,35 09х006 - 39,6 м, для труб Ø9,52 09х010 - 45,9 м, для труб Ø12,70 09х012 - 39,6 м, для
A37: труб Ø15,88 09х018 - 53,8 м, для труб Ø28,58 09х028 - 8,4 м
A39: предназначенных проектом № | U39: ПП2020РД-1.2-61.17-ОВ3, ПП2020РД-1.2-61.17-ОВ3.СО изм. 2 лист 2 | BY39: Шифр РД, изм., листы, Учётный лист ЖАН, письмо ООО "Газпром Инвест", письмо ООО "Транссроймеханизации" - при наличии
P40: (номер проекта, чертежа, дата)
A41: для строительства на участке : | U41: Этап I.II. Служебное здание АС
A42: (привязка, км/ПК)
D43: 1. Осмотром геометрических размеров и маркировки:
A44: совместно с проектом и сопроводительной документацией: | AK44: сертификат качества №ICG000637 от 22.03.2023, сертификат | BY44: Примеры написания:
...

Sheet 121р рефнет
A1: Министерство | L1: ПАО «Газпром» | AH1: Форма №3.3
A2: Объединение, трест | M2: АО "Газстройпроект" | AH2: Основание: ВСН 012-88 (Часть II)
A3: Участок: | F3: I.II | I3: этап | AN3: Миннефтегазстрой
AH4: Строительство: Аэропортовый комплекс на аэродроме «Левашово»
AH5: Объект: Аэропортовый комплекс на аэродроме «Левашово»
AH6: I этап. Сектор Гражданской авиации (создание технической возможности эксплуатации гражданских судов по МК-258)
AH8: Этап I.II.
Z9: АКТ № | AF9: АИР 1.2-61.17-ОВ3/121р
A10: о результатах проверки изделий/материалов
A12: Рефнет
A14: на соответствие техдокументации
AA15: от | AE15: 45337 | BW15: =AE15 -> 45337
A16: Составлен представителями:
A17: строительной организации | S17: =VLOOKUP(BJ17,подписанты!$B$3:$C$11,2,FALSE) -> Ведущий инженер МТО АО «Газстройпроект» | BJ17: Журавлев Ю.С.
T18: (должность, организация, фамилия, инициалы)
A19: службы контроля качества | S19: =VLOOKUP(BJ19,подписанты!$B$3:$C$11,2,FALSE) -> Инженер отдела технического надзора АО «Газстройпроект» | BJ19: Халыгов Э. А.
T20: (должность, организация, фамилия, инициалы)
A21: заказчика | S21: =VLOOKUP(BJ21,подписанты!$B$3:$C$11,2,FALSE) -> Начальник отдела организации и контроля материально-технического обеспечения Управления по реализации проектов авиационной инфраструктуры ГГС | BJ21: Тюкин Е.В.
T22: (должность, организация, фамилия, инициалы)
A23: в том, что произведен | O23: сплошной | BQ23: осмотр | BY23: Конструкив - сплошной вне зависимости объёма материала Выборочный при больших партиях (труб, штукатурки и т.д.), остальное сплошной
E24: (сплошной, выборочный )
A25: Рефнет-разветвитель универсальный Y1 - компл.
A27: предназначенных проектом № | U27: ПП2020РД-1.2-61.17-ОВ3.СО изм. лист | BY27: Шифр РД, изм., листы, Учётный лист ЖАН, письмо ООО "Газпром Инвест", письмо ООО "Транссроймеханизации" - при наличии
P28: (номер проекта, чертежа, дата)
A29: для строительства на участке : | U29: Этап I.II. Служебное здание АС
A30: (привязка, км/ПК)
D31: 1. Осмотром геометрических размеров и маркировки:
A32: совместно с проектом и сопроводительной документацией: | AK32: Паспорт изделия № 1632-15 от 23.10.2023; | BY32: Примеры написания:
A33: Сертификат соответствия № РОСС CN.НЕ06.Н04240 с 23.03.2023 по 22.03.2026
A34: (сертификатами, паспортами)
A35: на изделия установлено,
A36: что | D36: =A25 -> Рефнет-разветвитель универсальный Y1 - компл.
D37: (трубы, детали, силовые пояса и т.д.)
A38: по своим геометрическим размерам | Y38: н/п
Y39: (для труб указать диаметр, толщину стенки, мм, для отводов - угол изгиба, град. и т.д.)
A40: и номеру технических условий, указанному на изделии, | AJ40: соответствует | AT40: проекту (соответствует, не соответствует)
A41: рабочие чертежи № | Q41: =U27 -> ПП2020РД-1.2-61.17-ОВ3.СО изм. лист
D42: 2.Сопроводительная документация: | AA42: =AK32 -> Паспорт изделия № 1632-15 от 23.10.2023;
A43: =A33 -> Сертификат соответствия № РОСС CN.НЕ06.Н04240 с 23.03.2023 по 22.03.2026
V44: (паспорта, сертификаты) | BY44: трубы: диаметр 25 мм толщ. 3 мм, диаметр 32 мм толщ. 4 мм
...

Sheet 122р фреон
A1: Министерство | L1: ПАО «Газпром» | AH1: Форма №3.3
A2: Объединение, трест | M2: АО "Газстройпроект" | AH2: Основание: ВСН 012-88 (Часть II)
A3: Участок: | F3: I.II | I3: этап | AN3: Миннефтегазстрой
AH4: Строительство: Аэропортовый комплекс на аэродроме «Левашово»
AH5: Объект: Аэропортовый комплекс на аэродроме «Левашово»
AH6: I этап. Сектор Гражданской авиации (создание технической возможности эксплуатации гражданских судов по МК-258)
AH8: Этап I.II.
Z9: АКТ № | AF9: АИР 1.2-61.17-ОВ3/122р
A10: о результатах проверки изделий/материалов
A12: Фреон R410A
A14: на соответствие техдокументации
AA15: от | AE15: 45337 | BW15: =AE15 -> 45337
A16: Составлен представителями:
A17: строительной организации | S17: =VLOOKUP(BJ17,подписанты!$B$3:$C$11,2,FALSE) -> Ведущий инженер МТО АО «Газстройпроект» | BJ17: Журавлев Ю.С.
T18: (должность, организация, фамилия, инициалы)
A19: службы контроля качества | S19: =VLOOKUP(BJ19,подписанты!$B$3:$C$11,2,FALSE) -> Инженер отдела технического надзора АО «Газстройпроект» | BJ19: Халыгов Э. А.
T20: (должность, организация, фамилия, инициалы)
A21: заказчика | S21: =VLOOKUP(BJ21,подписанты!$B$3:$C$11,2,FALSE) -> Начальник отдела организации и контроля материально-технического обеспечения Управления по реализации проектов авиационной инфраструктуры ГГС | BJ21: Тюкин Е.В.
T22: (должность, организация, фамилия, инициалы)
A23: в том, что произведен | O23: сплошной | BQ23: осмотр | BY23: Конструкив - сплошной вне зависимости объёма материала Выборочный при больших партиях (труб, штукатурки и т.д.), остальное сплошной
E24: (сплошной, выборочный )
A25: Фреон R410A - 5 кг
A27: предназначенных проектом № | U27: ПП2020РД-1.2-61.17-ОВ3, ПП2020РД-1.2-61.17-ОВ3.СО изм. 2 лист 2 | BY27: Шифр РД, изм., листы, Учётный лист ЖАН, письмо ООО "Газпром Инвест", письмо ООО "Транссроймеханизации" - при наличии
P28: (номер проекта, чертежа, дата)
A29: для строительства на участке : | U29: Этап I.II. Служебное здание АС
A30: (привязка, км/ПК)
D31: 1. Осмотром геометрических размеров и маркировки:
A32: совместно с проектом и сопроводительной документацией: | AK32: паспорт безопасности материала б/н от 11.10.2023, сертификат | BY32: Примеры написания:
A33: соответствия №РОСС RU.32001.04ИБФ1.ОСП18.28370 с 20.01.2023 по 19.01.2026 | BY33: Паспорт №__ от __.__.____ г. Паспорт №б/н от __.__.____ г. на партию №__ Паспорт №б/н на партию №__ от __.__.____ г. Паспорт №б/н от __.__.____ г. (заводской номер №__)
A34: (сертификатами, паспортами)
A35: на изделия установлено,
A36: что | D36: =A25 -> Фреон R410A - 5 кг
D37: (трубы, детали, силовые пояса и т.д.)
A38: по своим геометрическим размерам | Y38: н/п
Y39: (для труб указать диаметр, толщину стенки, мм, для отводов - угол изгиба, град. и т.д.)
A40: и номеру технических условий, указанному на изделии, | AJ40: соответствует | AT40: проекту (соответствует, не соответствует)
A41: рабочие чертежи № | Q41: =U27 -> ПП2020РД-1.2-61.17-ОВ3, ПП2020РД-1.2-61.17-ОВ3.СО изм. 2 лист 2
D42: 2.Сопроводительная документация: | AA42: =AK32 -> паспорт безопасности материала б/н от 11.10.2023, сертификат
A43: =A33 -> соответствия №РОСС RU.32001.04ИБФ1.ОСП18.28370 с 20.01.2023 по 19.01.2026
V44: (паспорта, сертификаты) | BY44: трубы: диаметр 25 мм толщ. 3 мм, диаметр 32 мм толщ. 4 мм
...

Sheet 121р помпа, сифон, нагреватель
A1: Министерство | L1: ПАО «Газпром» | AH1: Форма №3.3
A2: Объединение, трест | M2: АО "Газстройпроект" | AH2: Основание: ВСН 012-88 (Часть II)
A3: Участок: | F3: I.II | I3: этап | AN3: Миннефтегазстрой
AH4: Строительство: Аэропортовый комплекс на аэродроме «Левашово»
AH5: Объект: Аэропортовый комплекс на аэродроме «Левашово»
AH6: I этап. Сектор Гражданской авиации (создание технической возможности эксплуатации гражданских судов по МК-258)
AH8: Этап I.II.
Z9: АКТ № | AF9: АИР 1.2-61.17-ОВ3/121р
A10: о результатах проверки изделий/материалов
A12: Дренажный нагреватель HD-50
A13: Сифон McAlpine MRNRV32C-PB
A14: Дренажная помпа Siccom Eco Flowatch
A16: на соответствие техдокументации
AA17: от | AE17: 45337 | BW17: =AE17 -> 45337
A18: Составлен представителями:
A19: строительной организации | S19: =VLOOKUP(BJ19,подписанты!$B$3:$C$11,2,FALSE) -> Ведущий инженер МТО АО «Газстройпроект» | BJ19: Журавлев Ю.С.
T20: (должность, организация, фамилия, инициалы)
A21: службы контроля качества | S21: =VLOOKUP(BJ21,подписанты!$B$3:$C$11,2,FALSE) -> Инженер отдела технического надзора АО «Газстройпроект» | BJ21: Халыгов Э. А.
T22: (должность, организация, фамилия, инициалы)
A23: заказчика | S23: =VLOOKUP(BJ23,подписанты!$B$3:$C$11,2,FALSE) -> Начальник отдела организации и контроля материально-технического обеспечения Управления по реализации проектов авиационной инфраструктуры ГГС | BJ23: Тюкин Е.В.
T24: (должность, организация, фамилия, инициалы)
A25: в том, что произведен | O25: сплошной | BQ25: осмотр | BY25: Конструкив - сплошной вне зависимости объёма материала Выборочный при больших партиях (труб, штукатурки и т.д.), остальное сплошной
E26: (сплошной, выборочный )
A27: Дренажный нагреватель HD-50 - 2 шт.,
A28: Сифон McAlpine MRNRV32C-PB - 3 шт.,
A29: Дренажная помпа Siccom Eco Flowatch - 11 шт.
A31: предназначенных проектом № | U31: ПП2020РД-1.2-61.17-ОВ3, ПП2020РД-1.2-61.17-ОВ3.СО изм. 2 лист 3 | BY31: Шифр РД, изм., листы, Учётный лист ЖАН, письмо ООО "Газпром Инвест", письмо ООО "Транссроймеханизации" - при наличии
P32: (номер проекта, чертежа, дата)
A33: для строительства на участке : | U33: Этап I.II. Служебное здание АС
A34: (привязка, км/ПК)
D35: 1. Осмотром геометрических размеров и маркировки:
A36: совместно с проектом и сопроводительной документацией: | AK36: Паспорт б/н от 14.11.2023, сертификат соответствия | BY36: Примеры написания:
A37: №РОСС RU C-RU.HB63.H01889 с 22.04.2022 по 21.04.2025, Паспорт изделия б/н 22.11.2023, информационное письмо | BY37: Паспорт №__ от __.__.____ г. Паспорт №б/н от __.__.____ г. на партию №__ Паспорт №б/н на партию №__ от __.__.____ г. Паспорт №б/н от __.__.____ г. (заводской номер №__)
A38: б/н от 10.09.2018, паспорт №8912 от 12.11.2023, Декларация о соответствии № ЕАЭС N RU Д-FR.PA03.B.80980/22
A39: с 26.05.2022 по 25.05.2027
A40: (сертификатами, паспортами)
A41: на изделия установлено,
A42: что | D42: =A27 -> Дренажный нагреватель HD-50 - 2 шт.,
D43: =A28 -> Сифон McAlpine MRNRV32C-PB - 3 шт.,
D44: =A29 -> Дренажная помпа Siccom Eco Flowatch - 11 шт.
...

Sheet 123р труба ппр, фитинги
A1: Министерство | L1: ПАО «Газпром» | AH1: Форма №3.3
A2: Объединение, трест | M2: АО "Газстройпроект" | AH2: Основание: ВСН 012-88 (Часть II)
A3: Участок: | F3: I.II | I3: этап | AN3: Миннефтегазстрой
AH4: Строительство: Аэропортовый комплекс на аэродроме «Левашово»
AH5: Объект: Аэропортовый комплекс на аэродроме «Левашово»
AH6: I этап. Сектор Гражданской авиации (создание технической возможности эксплуатации гражданских судов по МК-258)
AH8: Этап I.II.
Z9: АКТ № | AF9: АИР 1.2-61.17-ОВ3/123р
A10: о результатах проверки изделий/материалов
A12: Труба PP-R SDR11: Ø20, Ø25, Ø32
A13: Отвод: Ø20, Ø25
A14: Тройник: Ø20x20x20, Ø25x25x25, Ø32x32x32
A15: Тройник переходной Ø32x20x32
A16: Муфта переходная: Ø32x25, Ø32x20, Ø25x20
A18: на соответствие техдокументации
AA19: от | AE19: 45337 | BW19: =AE19 -> 45337
A20: Составлен представителями:
A21: строительной организации | S21: =VLOOKUP(BJ21,подписанты!$B$3:$C$11,2,FALSE) -> Ведущий инженер МТО АО «Газстройпроект» | BJ21: Журавлев Ю.С.
T22: (должность, организация, фамилия, инициалы)
A23: службы контроля качества | S23: =VLOOKUP(BJ23,подписанты!$B$3:$C$11,2,FALSE) -> Инженер отдела технического надзора АО «Газстройпроект» | BJ23: Халыгов Э. А.
T24: (должность, организация, фамилия, инициалы)
A25: заказчика | S25: =VLOOKUP(BJ25,подписанты!$B$3:$C$11,2,FALSE) -> Начальник отдела организации и контроля материально-технического обеспечения Управления по реализации проектов авиационной инфраструктуры ГГС | BJ25: Тюкин Е.В.
T26: (должность, организация, фамилия, инициалы)
A27: в том, что произведен | O27: сплошной | BQ27: осмотр | BY27: Конструкив - сплошной вне зависимости объёма материала Выборочный при больших партиях (труб, штукатурки и т.д.), остальное сплошной
E28: (сплошной, выборочный )
A29: Труба PP-R SDR11: Ø20 - 30 м, Ø25 - 12 м, Ø32 - 30 м,
A30: Угольник: Ø20 - 20 шт., Ø25 - 8 шт.,
A31: Тройник: Ø20x20x20 - 3 шт., Ø25x25x25 - 2 шт., Ø32x32x32 - 2 шт.,
A32: Тройник переходной Ø32x20x32 - 4 шт.,
A33: Муфта переходная: Ø32x25 - 2 шт., Ø32x20 - 2 шт., Ø25x20 - 2 шт.
A35: предназначенных проектом № | U35: ПП2020РД-1.2-61.17-ОВ3.СО изм. 1 лист 3 | BY35: Шифр РД, изм., листы, Учётный лист ЖАН, письмо ООО "Газпром Инвест", письмо ООО "Транссроймеханизации" - при наличии
P36: (номер проекта, чертежа, дата)
A37: для строительства на участке : | U37: Этап I.II. Служебное здание АС
A38: (привязка, км/ПК)
D39: 1. Осмотром геометрических размеров и маркировки:
A40: совместно с проектом и сопроводительной документацией: | AK40: Паспорт, техническое описание и инструкция по эксплуатации | BY40: Примеры написания:
A41: б/н от 24.11.2023, Свидетельство о государственной регистрации № RU.23.KK.08.013.E.000022.01.17 от 23.01.2017, | BY41: Паспорт №__ от __.__.____ г. Паспорт №б/н от __.__.____ г. на партию №__ Паспорт №б/н на партию №__ от __.__.____ г. Паспорт №б/н от __.__.____ г. (заводской номер №__)
A42: Информационное письмо Исх. № б/н от 19.05.2023, Паспорт, техническое описание и инструкция по эксплуатации б/н
A43: от 26.10.2023, Сертификат соответствия № какой из?
A44: (сертификатами, паспортами)
...

Sheet 125р труба капиялрная
A1: Министерство | L1: ПАО «Газпром» | AH1: Форма №3.3
A2: Объединение, трест | M2: АО "Газстройпроект" | AH2: Основание: ВСН 012-88 (Часть II)
A3: Участок: | F3: I.II | I3: этап | AN3: Миннефтегазстрой
AH4: Строительство: Аэропортовый комплекс на аэродроме «Левашово»
AH5: Объект: Аэропортовый комплекс на аэродроме «Левашово»
AH6: I этап. Сектор Гражданской авиации (создание технической возможности эксплуатации гражданских судов по МК-258)
AH8: Этап I.II.
Z9: АКТ № | AF9: АИР 1.2-61.17-ОВ3/125р
A10: о результатах проверки изделий/материалов
A12: Труба капиллярная Ø6 в гофрированной трубе (дренажный трубозавод):
A13: Ø16
A14: на соответствие техдокументации
AA15: от | AE15: 45337 | BW15: =AE15 -> 45337
A16: Составлен представителями:
A17: строительной организации | S17: =VLOOKUP(BJ17,подписанты!$B$3:$C$11,2,FALSE) -> Ведущий инженер МТО АО «Газстройпроект» | BJ17: Журавлев Ю.С.
T18: (должность, организация, фамилия, инициалы)
A19: службы контроля качества | S19: =VLOOKUP(BJ19,подписанты!$B$3:$C$11,2,FALSE) -> Инженер отдела технического надзора АО «Газстройпроект» | BJ19: Халыгов Э. А.
T20: (должность, организация, фамилия, инициалы)
A21: заказчика | S21: =VLOOKUP(BJ21,подписанты!$B$3:$C$11,2,FALSE) -> Начальник отдела организации и контроля материально-технического обеспечения Управления по реализации проектов авиационной инфраструктуры ГГС | BJ21: Тюкин Е.В.
T22: (должность, организация, фамилия, инициалы)
A23: в том, что произведен | O23: сплошной | BQ23: осмотр | BY23: Конструкив - сплошной вне зависимости объёма материала Выборочный при больших партиях (труб, штукатурки и т.д.), остальное сплошной
E24: (сплошной, выборочный )
A25: Труба ПВХ гибкая гофрированная: Ø16 - м,
A26: Трубка капиллярная Ø6 - м
A28: предназначенных проектом № | U28: ПП2020РД-1.2-61.17-ОВ3.СО изм. лист | BY28: Шифр РД, изм., листы, Учётный лист ЖАН, письмо ООО "Газпром Инвест", письмо ООО "Транссроймеханизации" - при наличии
P29: (номер проекта, чертежа, дата)
A30: для строительства на участке : | U30: Этап I.II. Служебное здание АС
A31: (привязка, км/ПК)
D32: 1. Осмотром геометрических размеров и маркировки:
A33: совместно с проектом и сопроводительной документацией: | AK33: Паспорт качества № 92135 от 04.10.2023; | BY33: Примеры написания:
A34: Сертификат соответствия №ЕАЭС RU C-RU.ПБ68.В.00559/21 с 04.10.2021 по 15.03.2026;
A35: Паспорт качества б/н от 28.11.2023, Сертификат соответствия № РОСС RU.АЖ49.Н01493 с 08.06.2021 по 07.06.2024
A36: (сертификатами, паспортами)
A37: на изделия установлено,
A38: что | D38: =A25 -> Труба ПВХ гибкая гофрированная: Ø16 - м,
D39: =A26 -> Трубка капиллярная Ø6 - м
D40: (трубы, детали, силовые пояса и т.д.)
A41: по своим геометрическим размерам | Y41: Ø16; Ø6
Y42: (для труб указать диаметр, толщину стенки, мм, для отводов - угол изгиба, град. и т.д.)
A43: и номеру технических условий, указанному на изделии, | AJ43: соответствует | AT43: проекту (соответствует, не соответствует)
...

Sheet 126р
A1: Министерство | L1: ПАО «Газпром» | AH1: Форма №3.3
A2: Объединение, трест | M2: АО "Газстройпроект" | AH2: Основание: ВСН 012-88 (Часть II)
A3: Участок: | F3: I.II | I3: этап | AN3: Миннефтегазстрой
AH4: Строительство: Аэропортовый комплекс на аэродроме «Левашово»
AH5: Объект: Аэропортовый комплекс на аэродроме «Левашово»
AH6: I этап. Сектор Гражданской авиации (создание технической возможности эксплуатации гражданских судов по МК-258)
AH8: Этап I.II.
Z9: АКТ № | AF9: АИР 1.2-61.17-ОВ3/126р
A10: о результатах проверки изделий/материалов
A12: Резиновая манжета 32/50
A13: Резиновая манжета 40/50
A14: Комперссионное соединение 110/50
A15: Самоуплотняющийся фитинг
A16: на соответствие техдокументации
AA17: от | AE17: 45337 | BW17: =AE17 -> 45337
A18: Составлен представителями:
A19: строительной организации | S19: =VLOOKUP(BJ19,подписанты!$B$3:$C$11,2,FALSE) -> Ведущий инженер МТО АО «Газстройпроект» | BJ19: Журавлев Ю.С.
T20: (должность, организация, фамилия, инициалы)
A21: службы контроля качества | S21: =VLOOKUP(BJ21,подписанты!$B$3:$C$11,2,FALSE) -> Инженер отдела технического надзора АО «Газстройпроект» | BJ21: Халыгов Э. А.
T22: (должность, организация, фамилия, инициалы)
A23: заказчика | S23: =VLOOKUP(BJ23,подписанты!$B$3:$C$11,2,FALSE) -> Начальник отдела организации и контроля материально-технического обеспечения Управления по реализации проектов авиационной инфраструктуры ГГС | BJ23: Тюкин Е.В.
T24: (должность, организация, фамилия, инициалы)
A25: в том, что произведен | O25: сплошной | BQ25: осмотр | BY25: Конструкив - сплошной вне зависимости объёма материала Выборочный при больших партиях (труб, штукатурки и т.д.), остальное сплошной
E26: (сплошной, выборочный )
A27: Резиновая манжета 32/50 - шт.,
A28: Резиновая манжета 40/50 - шт.,
A29: Комперссионное соединение 110/50 - шт.
A30: Самоуплотняющийся фитинг - шт. | BY30: Шифр РД, изм., листы, Учётный лист ЖАН, письмо ООО "Газпром Инвест", письмо ООО "Транссроймеханизации" - при наличии
A32: предназначенных проектом № | U32: ПП2020РД-1.2-61.17-ОВ3.СО изм. лист
P33: (номер проекта, чертежа, дата) | BY33: Примеры написания:
A34: для строительства на участке : | U34: Этап I.II. Служебное здание АС | BY34: Паспорт №__ от __.__.____ г. Паспорт №б/н от __.__.____ г. на партию №__ Паспорт №б/н на партию №__ от __.__.____ г. Паспорт №б/н от __.__.____ г. (заводской номер №__)
A35: (привязка, км/ПК)
D36: 1. Осмотром геометрических размеров и маркировки:
A37: совместно с проектом и сопроводительной документацией: | AK37: Технический паспорт и руководство по эксплуатации б/н
A38: от 07.11.2023, Информационное письмо исх. №1523/Л от 26.01.2022, Паспорт изделия б/н от 26.10.2023,
A39: Информационное письмо исх.№ОТК/109 от 10.09.2018, Паспорт б/н от 21.11.2023,
A40: Сертификат соответствия № РОСС RU.HE06.H12786 с 19.09.2023 по 18.09.2026
A41: (сертификатами, паспортами)
A42: на изделия установлено,
A43: что | D43: =A27 -> Резиновая манжета 32/50 - шт.,
...

Sheet 127р изоляция
A1: Министерство | L1: ПАО «Газпром» | AH1: Форма №3.3
A2: Объединение, трест | M2: АО "Газстройпроект" | AH2: Основание: ВСН 012-88 (Часть II)
A3: Участок: | F3: I.II | I3: этап | AN3: Миннефтегазстрой
AH4: Строительство: Аэропортовый комплекс на аэродроме «Левашово»
AH5: Объект: Аэропортовый комплекс на аэродроме «Левашово»
AH6: I этап. Сектор Гражданской авиации (создание технической возможности эксплуатации гражданских судов по МК-258)
AH8: Этап I.II.
Z9: АКТ № | AF9: АИР 1.2-61.17-ОВ3/126р
A10: о результатах проверки изделий/материалов
A12: Трубная изоляция K-Flex: 9хФ6; 9хФ10; 9хФ12; 13хФ15х2; 13хФ18х2; 13хФ22х2; 13хФ28х2;
A13: Трубная изоляция Unionflex:; 6хФ20х2; 6хФ25х2; 6хФ32х2
A14: на соответствие техдокументации
AA15: от | AE15: 45337 | BW15: =AE15 -> 45337
A16: Составлен представителями:
A17: строительной организации | S17: =VLOOKUP(BJ17,подписанты!$B$3:$C$11,2,FALSE) -> Ведущий инженер МТО АО «Газстройпроект» | BJ17: Журавлев Ю.С.
T18: (должность, организация, фамилия, инициалы)
A19: службы контроля качества | S19: =VLOOKUP(BJ19,подписанты!$B$3:$C$11,2,FALSE) -> Инженер отдела технического надзора АО «Газстройпроект» | BJ19: Халыгов Э. А.
T20: (должность, организация, фамилия, инициалы)
A21: заказчика | S21: =VLOOKUP(BJ21,подписанты!$B$3:$C$11,2,FALSE) -> Начальник отдела организации и контроля материально-технического обеспечения Управления по реализации проектов авиационной инфраструктуры ГГС | BJ21: Тюкин Е.В.
T22: (должность, организация, фамилия, инициалы)
A23: в том, что произведен | O23: сплошной | BQ23: осмотр | BY23: Конструкив - сплошной вне зависимости объёма материала Выборочный при больших партиях (труб, штукатурки и т.д.), остальное сплошной
E24: (сплошной, выборочный )
A25: Трубная изоляция K-Flex: 9хФ6 - м; 9хФ10 - м; 9хФ12 - м; 13хФ15х2 - м; 13хФ18х2 - м;
A26: 13хФ22х2 - м; 13хФ28х2 - м;
A27: Трубная изоляция Unionflex: 6хФ20х2 - м; 6хФ25х2 - м; 6хФ32х2 - м
A29: предназначенных проектом № | U29: ПП2020РД-1.2-61.17-ОВ3.СО изм. лист
P30: (номер проекта, чертежа, дата) | BY30: Примеры написания:
A31: для строительства на участке : | U31: Этап I.II. Служебное здание АС | BY31: Паспорт №__ от __.__.____ г. Паспорт №б/н от __.__.____ г. на партию №__ Паспорт №б/н на партию №__ от __.__.____ г. Паспорт №б/н от __.__.____ г. (заводской номер №__)
A32: (привязка, км/ПК)
D33: 1. Осмотром геометрических размеров и маркировки:
A34: совместно с проектом и сопроводительной документацией: | AK34: Паспорт № 5178500 - R0906515708 от 03.07.2023;
A35: Паспорт № 5178500 - R09010596708 от 10.07.2023; Паспорт № 5178500 - R09012719043 от 12.07.2023;
A36: Паспорт № 5178500 - R13015215607 от 24.07.2023; Паспорт № 5178500 - R13018214308 от 26.07.2023;
A37: Паспорт № 5178500 - R13022435608 от 12.07.2023; Паспорт № 5178500 - R13028435708 от 12.07.2023;
A38: Экспертное заключение № 77.01.12.П.002501.07.17 от 07.07.2017;
A39: Сертификат соответствия № RU C-RU.ПБ09.В.00294/21 с 17.12.2021 по 16.12.2026;
A40: Информационное письмо № 201 от 30.09.2014;
A41: Паспорт качества № 547 04.12.2023; Паспорт качества № 553 07.12.2023; Паспорт качества № 568 11.12.2023;
A42: Сертификат соответствия № АПБ.RU.ОС002/4.Н.01563 с 29.09.2021 по 28.09.2024;
A43: Сертификат соответствия № RU C-RU.ПБ09.В.00463/23 с 03.11.2023 по 02.11.2028.
...

Sheet 128р крепежные элементы
A1: Министерство | L1: ПАО «Газпром» | AH1: Форма №3.3
A2: Объединение, трест | M2: АО "Газстройпроект" | AH2: Основание: ВСН 012-88 (Часть II)
A3: Участок: | F3: I.II | I3: этап | AN3: Миннефтегазстрой
AH4: Строительство: Аэропортовый комплекс на аэродроме «Левашово»
AH5: Объект: Аэропортовый комплекс на аэродроме «Левашово»
AH6: I этап. Сектор Гражданской авиации (создание технической возможности эксплуатации гражданских судов по МК-258)
AH8: Этап I.II.
Z9: АКТ № | AF9: АИР 1.2-61.17-ОВ3/128р
A10: о результатах проверки изделий/материалов
A12: Крепежные элементы
A13: на соответствие техдокументации
AA14: от | AE14: 45337 | BW14: =AE14 -> 45337
A15: Составлен представителями:
A16: строительной организации | S16: =VLOOKUP(BJ16,подписанты!$B$3:$C$11,2,FALSE) -> Ведущий инженер МТО АО «Газстройпроект» | BJ16: Журавлев Ю.С.
T17: (должность, организация, фамилия, инициалы)
A18: службы контроля качества | S18: =VLOOKUP(BJ18,подписанты!$B$3:$C$11,2,FALSE) -> Инженер отдела технического надзора АО «Газстройпроект» | BJ18: Халыгов Э. А.
T19: (должность, организация, фамилия, инициалы)
A20: заказчика | S20: =VLOOKUP(BJ20,подписанты!$B$3:$C$11,2,FALSE) -> Начальник отдела организации и контроля материально-технического обеспечения Управления по реализации проектов авиационной инфраструктуры ГГС | BJ20: Тюкин Е.В.
T21: (должность, организация, фамилия, инициалы)
A22: в том, что произведен | O22: сплошной | BQ22: осмотр | BY22: Конструкив - сплошной вне зависимости объёма материала Выборочный при больших партиях (труб, штукатурки и т.д.), остальное сплошной
E23: (сплошной, выборочный )
A24: Крепежные элементы - кг
A26: предназначенных проектом № | U26: ПП2020РД-1.2-61.17-ОВ3.СО изм. лист
P27: (номер проекта, чертежа, дата) | BY27: Примеры написания:
A28: для строительства на участке : | U28: Этап I.II. Служебное здание АС | BY28: Паспорт №__ от __.__.____ г. Паспорт №б/н от __.__.____ г. на партию №__ Паспорт №б/н на партию №__ от __.__.____ г. Паспорт №б/н от __.__.____ г. (заводской номер №__)
A29: (привязка, км/ПК)
D30: 1. Осмотром геометрических размеров и маркировки:
A31: совместно с проектом и сопроводительной документацией: | AK31: Сертификат качества № 312123-078 от 15.01.2024,
A32: Сертификат соответствия №РОСС CN.АЖ49.Н04278 с 27.07.2023 по 26.07.2026,
A33: Сертификат соответствия №РОСС CN.АЖ49.Н04313 с 07.08.2023 по 06.08.2026,
A34: Паспорт изделия №080483 от 18.01.2024
A35: Сертификат соответствия № РОСС RU.32001.04ИБФ1.ОСП18.25939 с 14.11.2022 по 13.11.2025
A36: (сертификатами, паспортами)
A37: на изделия установлено,
A38: что | D38: =A24 -> Крепежные элементы - кг
D39: (трубы, детали, силовые пояса и т.д.)
A40: по своим геометрическим размерам | Y40: н/п | BY40: трубы: диаметр 25 мм толщ. 3 мм, диаметр 32 мм толщ. 4 мм
Y41: (для труб указать диаметр, толщину стенки, мм, для отводов - угол изгиба, град. и т.д.) | BY41: По поворотам, отводам и т.д. необходимо уточнее в МТО ГСП
A42: и номеру технических условий, указанному на изделии, | AJ42: соответствует | AT42: проекту (соответствует, не соответствует)
A43: рабочие чертежи № | Q43: =U26 -> ПП2020РД-1.2-61.17-ОВ3.СО изм. лист
...

Sheet подписанты
A2: Составлен представителями: | B2: ФИО | C2: Должность | D2: с | E2: до
A3: строительной организации | B3: Кострова Н.Л. | C3: Руководитель группы МТО АО «Газстройпроект» | D3: 44927 | E3: 45337
A4: строительной организации | B4: Журавлев Ю.С. | C4: Ведущий инженер МТО АО «Газстройпроект» | D4: 45337 | E4: 45657
A5: службы контроля качества | B5: Халыгов Э. А. | C5: Инженер отдела технического надзора АО «Газстройпроект» | D5: 45166 | E5: 45657
A6: службы контроля качества | B6: Ткаченко С.В. | C6: Ведущий инженер отдела технического надзора АО «Газстройпроект» | D6: 44927 | E6: 45166
A7: службы контроля качества | B7: Будянский А.С. | C7: Инженер отдела технического надзора АО «Газстройпроект» | D7: 45278 | E7: 45342 | F7: на период отпуска Ткаченко, на период отпуска Халыгова август 2024
A8: заказчика | B8: Лбова П.А. | C8: Главный специалист Отдела организации и контроля материально-технического обеспечения Управления по реализации проектов г. Санкт-Петербург ООО «Газпром инвест» | D8: 44927 | E8: 45657
A9: заказчика | B9: Тюкин Е.В. | C9: Начальник отдела организации и контроля материально-технического обеспечения Управления по реализации проектов авиационной инфраструктуры ГГС | F9: подписывает сейчас
B11: Тишаков ? ? | C11: Ведущий инженер МТО АО «Газстройпроект»

Sheet Лист общих данных
A5: № по ГП | B5: Наименование объекта | C5: Шифр чертежа КМ | D5: № последнего изм
A6: 61.6 | B6: Этап I.II. Топливозаправочный пункт. Операторная ТЗП | C6: ПП2020РД-1.2-61.6-ОВ1
A7: 61.17 | B7: Этап I.II. Служебное здание АС | C7: ПП2020РД-1.2-61.17-ОВ1
A8: 61.2 | B8: Этап I.II. Служебное здание ССТ со столовой | C8: ПП2020РД-1.2-61.2-ОВ1
A9: 56 | B9: Этап I.II. Аварийно-спасательная станция | C9: ПП2020РД-1.2-56-ОВ1
A10: 57 | B10: Этап I.II. Контрольно-пропускной пункт (КПП) с караульным помещением | C10: ПП2020РД-1.2-57-ОВ1
A11: 110 | B11: Этап I.II. Служебное здание службы электросвето-технического обеспечения полетов (ЭСТОП) | C11: ПП2020РД-1.2-110-ОВ1
A12: 111 | B12: Этап I.II. Складской комплекс службы ЭСТОП, сблокированный со стоянкой автомобилей | C12: ПП2020РД-1.2-111-ОВ1
