Workbook

Sheet 123р труба ппр, фитинги
A1: Министерство | L1: ПАО «Газпром» | AH1: Форма №3.3
A2: Объединение, трест | M2: АО "Газстройпроект" | AH2: Основание: ВСН 012-88 (Часть II)
A3: Участок: | F3: I.II | I3: этап | AN3: Миннефтегазстрой
AH4: Строительство: Аэропортовый комплекс на аэродроме «Левашово»
AH5: Объект: Аэропортовый комплекс на аэродроме «Левашово»
AH6: I этап. Сектор Гражданской авиации (создание технической возможности эксплуатации гражданских судов по МК-258)
AH8: Этап I.II.
Z9: АКТ № | AF9: АИР 1.2-61.17-ОВ3/5
A10: о результатах проверки изделий/материалов
A12: Труба PP-R SDR11: Ø20, Ø25, Ø32;
A13: Капиллярная трубка Ø6;
A14: Труба ПВХ гофрированная d16;
A15: Отвод 90°: Ø20, Ø25, Ø32;
A16: Отвод 45°: Ø20, Ø32;
A17: Тройник PPR: Ø20/Ø20/Ø20, Ø25/Ø20/Ø25, Ø32/Ø20/Ø32, Ø32/Ø32/Ø32;
A18: Переход PPR : Ø25/Ø20, Ø32/Ø20, Ø32/Ø25;
A19: Заглушка PPR Ø20.
A21: на соответствие техдокументации
AA22: от | AE22: 45285 | BW22: =AE22 -> 45285
A23: Составлен представителями:
A24: строительной организации | S24: =VLOOKUP(BJ24,подписанты!$B$3:$C$11,2,FALSE) -> Руководитель группы МТО АО «Газстройпроект» | BJ24: Кострова Н.Л.
T25: (должность, организация, фамилия, инициалы)
A26: службы контроля качества | S26: =VLOOKUP(BJ26,подписанты!$B$3:$C$11,2,FALSE) -> Инженер отдела технического надзора АО «Газстройпроект» | BJ26: Халыгов Э. А.
T27: (должность, организация, фамилия, инициалы)
A28: заказчика | S28: =VLOOKUP(BJ28,подписанты!$B$3:$C$11,2,FALSE) -> Начальник отдела организации и контроля материально-технического обеспечения Управления по реализации проектов авиационной инфраструктуры ГГС | BJ28: Тюкин Е.В.
T29: (должность, организация, фамилия, инициалы)
A30: в том, что произведен | O30: сплошной | BQ30: осмотр | BY30: Конструкив - сплошной вне зависимости объёма материала Выборочный при больших партиях (труб, штукатурки и т.д.), остальное сплошной
E31: (сплошной, выборочный )
A32: Труба PP-R SDR11: Ø20 - 21,4 м, Ø25 - 4,43 м, Ø32 - 28,4 м;
A33: Капиллярная трубка (шланг однослойный ПВХ) - 7,6 м;
A34: Труба ПВХ гофрированная - 7,6 м;
A35: Отвод 90°: Ø20 - 14 шт., Ø25 - 1 шт., Ø32 - 4 шт.;
A36: Отвод 45°: Ø20 - 2 шт., Ø32 - 3 шт.;
A37: Тройник PPR: Ø20/Ø20/Ø20 - 4 шт., Ø25/Ø20/Ø25 - 4 шт., Ø32/Ø20/Ø32 - 6 шт., Ø32/Ø32/Ø32 - 2 шт.;
A38: Переход PPR : Ø25/Ø20 - 2 шт., Ø32/Ø20 - 1 шт., Ø32/Ø25 -3 шт.;
A39: Заглушка PPR - 11 шт.
A41: предназначенных проектом № | U41: ПП2020РД-1.2-61.17-ОВ3.СО изм.2, л. 2-3 | BY41: Шифр РД, изм., листы, Учётный лист ЖАН, письмо ООО "Газпром Инвест", письмо ООО "Транссроймеханизации" - при наличии
P42: (номер проекта, чертежа, дата)
A43: для строительства на участке : | U43: Этап I.II. Служебное здание АС
A44: (привязка, км/ПК)
...

Sheet 126р
A1: Министерство | L1: ПАО «Газпром» | AH1: Форма №3.3
A2: Объединение, трест | M2: АО "Газстройпроект" | AH2: Основание: ВСН 012-88 (Часть II)
A3: Участок: | F3: I.II | I3: этап | AN3: Миннефтегазстрой
AH4: Строительство: Аэропортовый комплекс на аэродроме «Левашово»
AH5: Объект: Аэропортовый комплекс на аэродроме «Левашово»
AH6: I этап. Сектор Гражданской авиации (создание технической возможности эксплуатации гражданских судов по МК-258)
AH8: Этап I.II.
Z9: АКТ № | AF9: АИР 1.2-61.17-ОВ3/6
A10: о результатах проверки изделий/материалов
A13: Комперссионное соединение Ø110/Ø50
A14: Резиновая манжета Ø50/Ø32
A16: на соответствие техдокументации
AA17: от | AE17: 45337 | BW17: =AE17 -> 45337
A18: Составлен представителями:
A19: строительной организации | S19: =VLOOKUP(BJ19,подписанты!$B$3:$C$11,2,FALSE) -> Ведущий инженер МТО АО «Газстройпроект» | BJ19: Журавлев Ю.С.
T20: (должность, организация, фамилия, инициалы)
A21: службы контроля качества | S21: =VLOOKUP(BJ21,подписанты!$B$3:$C$11,2,FALSE) -> Инженер отдела технического надзора АО «Газстройпроект» | BJ21: Халыгов Э. А.
T22: (должность, организация, фамилия, инициалы)
A23: заказчика | S23: =VLOOKUP(BJ23,подписанты!$B$3:$C$11,2,FALSE) -> Начальник отдела организации и контроля материально-технического обеспечения Управления по реализации проектов авиационной инфраструктуры ГГС | BJ23: Тюкин Е.В.
T24: (должность, организация, фамилия, инициалы)
A25: в том, что произведен | O25: сплошной | BQ25: осмотр | BY25: Конструкив - сплошной вне зависимости объёма материала Выборочный при больших партиях (труб, штукатурки и т.д.), остальное сплошной
E26: (сплошной, выборочный )
A28: Комперссионное соединение Ø110/Ø50
A29: Резиновая манжета Ø50/Ø32
A31: предназначенных проектом № | U31: ПП2020РД-1.2-61.17-ОВ3.СО изм. лист
P32: (номер проекта, чертежа, дата) | BY32: Примеры написания:
A33: для строительства на участке : | U33: Этап I.II. Служебное здание АС | BY33: Паспорт №__ от __.__.____ г. Паспорт №б/н от __.__.____ г. на партию №__ Паспорт №б/н на партию №__ от __.__.____ г. Паспорт №б/н от __.__.____ г. (заводской номер №__)
A34: (привязка, км/ПК)
D35: 1. Осмотром геометрических размеров и маркировки:
A36: совместно с проектом и сопроводительной документацией: | AK36: Технический паспорт и руководство по эксплуатации б/н
A37: от 07.11.2023, Информационное письмо исх. №1523/Л от 26.01.2022, Паспорт изделия б/н от 26.10.2023,
A38: Информационное письмо исх.№ОТК/109 от 10.09.2018, Паспорт б/н от 21.11.2023,
A39: Сертификат соответствия № РОСС RU.HE06.H12786 с 19.09.2023 по 18.09.2026
A40: (сертификатами, паспортами)
A41: на изделия установлено,
A42: что | D42: =A27 -> 0
D43: =A28 -> Комперссионное соединение Ø110/Ø50
D44: =A29 -> Резиновая манжета Ø50/Ø32
D45: =#REF! -> #REF!
D46: (трубы, детали, силовые пояса и т.д.)
...

Sheet подписанты
A2: Составлен представителями: | B2: ФИО | C2: Должность | D2: с | E2: до
A3: строительной организации | B3: Кострова Н.Л. | C3: Руководитель группы МТО АО «Газстройпроект» | D3: 44927 | E3: 45337
A4: строительной организации | B4: Журавлев Ю.С. | C4: Ведущий инженер МТО АО «Газстройпроект» | D4: 45337 | E4: 45657
A5: службы контроля качества | B5: Халыгов Э. А. | C5: Инженер отдела технического надзора АО «Газстройпроект» | D5: 45166 | E5: 45657
A6: службы контроля качества | B6: Ткаченко С.В. | C6: Ведущий инженер отдела технического надзора АО «Газстройпроект» | D6: 44927 | E6: 45166
A7: службы контроля качества | B7: Будянский А.С. | C7: Инженер отдела технического надзора АО «Газстройпроект» | D7: 45278 | E7: 45342 | F7: на период отпуска Ткаченко, на период отпуска Халыгова август 2024
A8: заказчика | B8: Лбова П.А. | C8: Главный специалист Отдела организации и контроля материально-технического обеспечения Управления по реализации проектов г. Санкт-Петербург ООО «Газпром инвест» | D8: 44927 | E8: 45657
A9: заказчика | B9: Тюкин Е.В. | C9: Начальник отдела организации и контроля материально-технического обеспечения Управления по реализации проектов авиационной инфраструктуры ГГС | F9: подписывает сейчас
B11: Тишаков ? ? | C11: Ведущий инженер МТО АО «Газстройпроект»

Sheet Лист общих данных
A5: № по ГП | B5: Наименование объекта | C5: Шифр чертежа КМ | D5: № последнего изм
A6: 61.6 | B6: Этап I.II. Топливозаправочный пункт. Операторная ТЗП | C6: ПП2020РД-1.2-61.6-ОВ1
A7: 61.17 | B7: Этап I.II. Служебное здание АС | C7: ПП2020РД-1.2-61.17-ОВ1
A8: 61.2 | B8: Этап I.II. Служебное здание ССТ со столовой | C8: ПП2020РД-1.2-61.2-ОВ1
A9: 56 | B9: Этап I.II. Аварийно-спасательная станция | C9: ПП2020РД-1.2-56-ОВ1
A10: 57 | B10: Этап I.II. Контрольно-пропускной пункт (КПП) с караульным помещением | C10: ПП2020РД-1.2-57-ОВ1
A11: 110 | B11: Этап I.II. Служебное здание службы электросвето-технического обеспечения полетов (ЭСТОП) | C11: ПП2020РД-1.2-110-ОВ1
A12: 111 | B12: Этап I.II. Складской комплекс службы ЭСТОП, сблокированный со стоянкой автомобилей | C12: ПП2020РД-1.2-111-ОВ1
